Workbook
Name Z_4076B397_909E_4026_BE11_525A508BFFEA_.wvu.Cols: Einzel!$D:$Y

Sheet Favoriten
A1: Gesellschaften | B1: Werner | C1: Volker | D1: Hans Jürgen | E1: Frank M. | F1: Frank H. | G1: Tommy | H1: Abrechnungen
A2: Aachener Bausparkasse | C2: x | E2: x
A3: abc-teleconsult
A4: ACE European Group Limited Direktion für Deutschland
A5: AdvoCard (Generali)
A6: Allianz Sach | B6: x | C6: x | D6: x | E6: x | G6: x
A7: Deutsche Lebensversicherung AG (Allianz) | B7: x | E7: x
A8: Allianz Leben | B8: x | C8: x | D8: x | E8: x | F8: X
A9: Allianz Kranken | B9: x
A10: Alte Leipziger Sach und Leben | B10: x | C10: x | E10: x | G10: x
A11: Alte Leipziger Bauspar AG | C11: x | E11: x | G11: x
A12: Ammerländer | B12: x | E12: x | G12: x
A13: Amex | E13: (X)
A14: AOK Plus | B14: x | C14: x | G14: x
A15: ARAG Versicherungen | C15: x | G15: x
A16: ARAG Krankenversicherungen
A17: ARAG Rectsschutzversicherung | B17: x | C17: x | D17: x
A18: ASC
A19: Apella | E19: (x)
A20: HDI (Aspecta)
A21: AUXILIA Rechtsschutz-Versicherungs AG | B21: x | C21: x | E21: x | G21: x
A22: AAB Augsburger Aktienbank (Invers)
A23: AXA/DBV Kranken | B23: x | C23: x | D23: x | E23: xx
A24: Baden-Badener | C24: x | G24: x | H24: Zurich
A25: Barmenia | B25: x | C25: x | D25: x
A26: Adcuri | B26: x | C26: x | G26: x
A27: Basler (Sach) | B27: x | C27: x | D27: x | G27: x
A28: Basler Lebensversicherung AG | B28: x
A29: Basler Service GmbH | B29: x | C29: x | D29: x | E29: x
A30: BKM Bausparkasse Mainz | C30: x | G30: x
A31: BCA
A32: die Bayerische (ex BBV) | B32: x | C32: x | E32: x | G32: x
A33: BHW (Invers) | C33: x
A34: Brandgilde Versicherung | B34: x | D34: x
A35: Canada Life | B35: x | C35: x | D35: x | G35: x
A36: carglass | B36: x | C36: x | G36: x
A37: Care Concept | C37: x | D37: x | E37: x
A38: Concordia | B38: x | C38: x | D38: x | G38: x
A39: Condor Klass. LV/BU / Optima
A40: Condor Leben (FLV) / Optima | D40: x | E40: x | F40: X
...

Sheet Tools
A1: Firma | B1: Name | C1: Registrierungspaßwort | D1: Benutzername | E1: Paßwort | F1: Sonstiges | G1: Web-Zugang | H1: Ansprechpartner
A2: Zurich | B2: Beratungsnavigator | C2: Navigator3.0 | D2: werner.petri@meinberaterhaus.de | E2: Wer57fra$ | G2: www.mach-plus-mit-protection.de | H2: Zurich, Herr Patrick Wiertz, 0228 / 268 25 23 / patrick.wiertz@zurich.com
A3: BKM Bausparkasse Mainz | B3: KIS | D3: 9900056806314 | E3: 2FifpLSg | F3: Zertifikat | G3: https://kunden.bkm.de/cas/login? | H3: Herr Schäfer
A4: VHV | B4: MAXX-Net
A5: VHV | B5: VHV-Tarife
A6: Concordia | B6: COPRA
A7: Easy Login (Web) | B7: Easy-Versicherungsportale-Login | D7: EL11827 | E7: wer57fra | F7: Token | G7: www.easy-login.de
A8: Easy Login | B8: Easy-Client | D8: EL11827 | E8: wer57fra | F8: Token
A9: ELBE (Online) SdV | B9: ELBE | D9: 205703 | E9: kugecufa891 | G9: https://www.plan25.de/login.elbe
A10: Franke & Bornberg | B10: fb-beraterwelt (ex fb-xpert) | D10: petri | E10: vowe2014
A11: HDI | B11: Firmen Digital | G11: https://www.hdi.de/apps
A12: Ideenwerk
A13: Interrisk
A14: Kassensuche GmbH | B14: gesetzlichkrankenkassen.de | D14: WernerPetri | E14: 98527 | F14: 2356 | G14: www.makleraktiv.de
A15: R+V | B15: R+V Connect | D15: rom0s2s | E15: Wer57fra
A16: DATEV
A17: Versicherungsmarkt | B17: VM-Connect
A18: BCA | B18: BusinessPlus
A19: Procheck24 | D19: petri | E19: sonne
A20: Rhion
A21: Invers | B21: IMA
A22: Inveda | B22: IMA-Sync
A23: ASC | B23: ASC-Easy
A24: NAFI | B24: NAFI-Web
A25: SEB | B25: SEB-App | D25: BeraterHaus | E25: F31309H11
A26: Inveda | B26: IMA | D26: verwaltung@beraterhaus | E26: wer57fra
A27: SdV | B27: Schutzvereinigung der Vermittler | D27: SDV-20.902 | E27: 5GJBBp | G27: https://sdv-online.de/
A28: BauFinex | B28: Finanzierungsplattform | D28: volker-tippmann-7961 | E28: Dbhisjs61& | G28: https://www.baufinex.de/marktplatz/
A29: Starpool | B29: Finanzierungsplattform | D29: volker_tippmann | E29: Starpool$1 | G29: www.starpool.de
A30: Dr. Klein (Kreher) | B30: Finanzierungsplattform | E30: MBH2020! | G30: http://cloud.drklein.de/index.php/s/XN2J4YLngxiEXGY
A31: MSC Fondskonzept | B31: Investmentplattform
A32: Google-Kalender | B32: Web-Browser / Google / Kalenender | D32: dasberaterhaus@gmail.com | E32: Berater&Co. | G32: https://calendar.google.com/calendar/u/0/r/week
A34: BeraterHaus INTERN
A35: VEMA | B35: Paßwortverwaltung Makler-Extranets
A36: Fritz!Box | B36: Benutzer | D36: Volker | E36: persönlich erfragen
D37: Alex | E37: persönlich erfragen
A38: Server | B38: Zentrale | D38: Persönlich erfragen | E38: persönlich erfragen
A39: PC-Netzwerk | B39: Innendienst 1 | D39: buero1 | E39: buero2009
B40: Innendienst 2 | D40: buero2 | E40: buero2009
B41: Innendienst 3 | D41: buero3 | E41: buero2009
...

Sheet GDV
A1: Gesellschaft | B1: Zugang | C1: Schlüssel | D1: Datenabholung | E1: Intervall | F1: POST | G1: GDV
A2: Adcuri (Barmenia) | F2: AMS/BiPro
A3: AIG (ex Marke WüBa) | B3: berat1pt | C3: Dbhjstr61is | D3: https://www.aigportal.de/pls/WUEBANET/GDV_DOWNLOAD_PUBLIC.DOWNLOAD_GDV?p_GJG_ID=66077&p_GJL_ID=11700&p_type=FILE | G3: 44788
A4: Allianz | B4: https://go-makler.allianz.de/gdv_app/Intranet/gdv | D4: Portal / Zertifikat | E4: mtl | F4: AMS/BiPro | G4: 43977 | I4: Nur Gesamtbestand lieferbar, nach telef. Info Frau Haus 17.05.2019
A5: Alte Leipziger / Hallesche / Rechtschutz Union | B5: petri.w | C5: wer57fra | D5: https://www.vermittlerportal.de/Appserver/vmp/GdvDownload/Download/Download | E5: mtl | F5: AMS/BiPro | G5: 43731 | H5: 43115
A6: ARAG | B6: MP02723 | D6: https://www.arag-partnervertrieb.de/ | G6: 43928
A7: ASC (AXA, HKD, Basler, …) | B7: Lieferung Gesamtbestand | C7: 98527 | D7: Info per Mail | E7: hlbj. | G7: 43672
A8: Auxilia_107175 | B8: https://portal.ks-auxilia.de/ng/#/vermittler/startseite | C8: 981263 | D8: Portal | E8: mtl | G8: 43881
A9: Auxilia_108980 | B9: https://portal.ks-auxilia.de/ng/#/vermittler/startseite | D9: Portal | E9: mtl. | G9: 43115 | H9: 43318
A10: Auxilia_112366 | B10: https://portal.ks-auxilia.de/ng/#/vermittler/startseite | C10: 631723 | D10: Portal | E10: mtl. | G10: 43444
A11: Advocard | D11: über Generali | G11: 43115
A12: AXA | B12: https://entry.axa.de/portalpostfach/ | D12: Portal / AMS | E12: mtl | G12: 44764 | H12: 43318 | K12: Bestandsänderung
A13: Baden-Badener (Zurich) | B13: 782644 | C13: uWybH3v6Ys | D13: https://www.bb-maklerwelt.de/Extranet/pages/peb/peb.faces | E13: mtl | F13: AMS/BiPro | G13: 43307 | H13: 43115
A14: Barmenia | D14: eBASIS-Abholung | F14: AMS/BiPro | G14: 43881
A15: Basler | D15: PW: MO#600688
A16: BSG Basler | C16: 98527 | D16: https://vema.basler-service.de | F16: AMS/BiPro | G16: 43693
A17: Canada Life | D17: keine GDV-Daten
A18: Concordia | B18: C05723 (geht nur mit WinZip) | C18: S0lVFqY1FD3X | D18: https://ftp.v-d-v.de | G18: 43914 | H18: sf25897pp Passwort für die zip-Datei
A19: Condor | F19: AMS/BiPro | H19: 43318
A20: Continentale / Europa | F20: AMS/BiPro | G20: 43977 | K20: Gesamtbestand
A21: Dialog | B21: 480203 | C21: eymzstbYwm4Z4H
A22: Degenia | D22: keine GDV-Daten
A23: Athora (Athena, Delta Lloyd) | B23: 4187038 | C23: Mein703? | D23: https://vermittlerservice.athene.de/vermittlerservice/download.do | E23: mtl. | G23: 43115
A24: Deurag | B24: petri | C24: wer57fra | D24: https://www.deurag.de/deurag/vertriebspartner/gdv-datensatze/daten.html | E24: mtl | G24: 43881 | H24: 43115 | K24: Bestandsänderung
A25: die Bayerische (ex BBV) | B25: MAK940862-0001 | C25: wer57fra | D25: https://www.bbv.de/cmweb/GdvDownloadServlet | E25: mtl | G25: 43886 | H25: 43115
A26: Die Hinterbliebenenkasse
A27: Ergo (DKV/DAS/Victoria) | B27: OM_E886985_TiVo | C27: 1J3VydAkY | D27: https://www.datenbereitstellung.de/gdvUI/Makler/Download.aspx | E27: mtl | G27: 22082022 | H27: 43115
A28: Dialog (ex Generali) | C28: G122700A/wer57fra | D28: https://prismavfsprod.generali.de/vfs/ | E28: mtl | F28: AMS/BiPro | G28: 43451 | H28: 43116
A29: Gothaer | C29: Goth123$ | D29: https://makler.gothaer.de/app/GDV-Online/Start | F29: AMS/BiPro | G29: 43880 | H29: 43318
A30: GVO | C30: GVOPortal | D30: www.g-v-o.de | G30: 43118
A31: Hanse-Merkur | B31: https://www.hansemerkur.de/maklersupport/ | C31: QQPKFAQN | D31: Portal (Infomail) | E31: mtl | G31: 44768
A32: HDI-Leben / Aspecta | B32: berater09 | C32: Beraterhaus2018 | D32: Portal | E32: mtl | F32: AMS/BiPro | G32: 43441
A33: HDI-Sach | B33: berater09 | C33: Beraterhaus2018 | D33: Portal | E33: mtl | F33: AMS/BiPro | G33: 43441
A34: Helvetia | D34: Portal | E34: mtl
A35: HKD | D35: per Mail (Herr Kalus) | E35: 43914 | F35: AMS/BiPro | G35: 44806 | H35: 43115
A36: Ideal | D36: Mail | E36: hlbj. | G36: 43977
A37: Inter | D37: nur Excel-Listen
A38: Interlloyd | D38: Portal (Infomail) | E38: mtl | G38: 43442 | H38: 43318
A39: Interrisk | D39: Portal (Infomail) | E39: mtl | G39: 44809 | H39: 43318
A40: Invers | D40: https://secure.invers-gruppe.de/login.htm | E40: mtl | G40: 43731
...

Sheet Passwörter_Agenturen
A1: lfd.Nr. A | B1: Benutzername/Maklernummer | C1: Passwort | D1: Sonstiges | E1: Gesellschaft | F1: Schreibweise | G1: lfd.Nr.B | H1: Gesellschaft / Partner | I1: VEMA | J1: BeraterHaus | K1: ASC | L1: Invers | M1: Jung DMS | N1: maxpool | O1: AMEX | P1: Petri | Q1: Tippmann | R1: Röder | S1: Hesselbarth | T1: Furch | U1: Hartkopf | V1: Hildebrandt | W1: Hollatz | X1: Hopf | Y1: Kramer | Z1: Schellhorn | AA1: Lins | AB1: Littig | AC1: Lobe | AD1: Scharlach | AE1: Weißkopf | AF1: Schumacher | AG1: Autohaus Hüther | AH1: Motorrad Henkel | AI1: Reif | AJ1: Malzahn
A2: A1 | B2: 900426758302016 | C2: wer57fra | E2: AAB Augsburger Aktienbank | G2: B1 | H2: AAB Augsburger Aktienbank (Invers)
A3: A2 | E3: Aachener Bausparkasse | G3: B2 | H3: Aachener Bausparkasse | J3: 100015718 | AI3: Kroschwald / Invers
A4: A3 | E4: abc-teleconsult | G4: B3 | H4: abc-teleconsult | AI4: 20052
A5: A4 | E5: ACE European Group Limited Direktion für Deutschland | G5: B4 | H5: ACE European Group Limited Direktion für Deutschland | I5: 2202_VEMA | AI5: 71518
A6: A5 | B6: 950086739 | C6: wer57fra | E6: Adcuri | G6: B5 | H6: Adcuri | I6: 950212022 | J6: 950086739
A7: A6 | B7: 950094925 | C7: 7305ba3d | E7: Adcuri | G7: B6 | H7: Adcuri (Invers) | L7: 950094925
A8: A7 | B8: 950212022 | C8: BHSidJS61 | E8: Adcuri | G8: B7 | H8: Adcuri (VEMA) | I8: 950212022 | J8: 950205963 alt
A9: A8 | B9: info@suhlfinanz.de | C9: wer57fra | E9: CSS | G9: B8 | H9: Advigon (ex CSS 80002841) | I9: 3780145 | J9: 3780145
A10: A9 | E10: AdvoCard (Generali) | G10: B9 | H10: AdvoCard (Dialog) | I10: 106151 | J10: 70/5523/00122700 | P10: 590/5509
A11: A10 | B11: berat1pt | C11: BHS61Jstr | D11: Maklerportal | E11: AIG (ex WÜBA) | F11: 90017016989 | G11: B10 | H11: AIG Europe Limited (Marke WüBa) | I11: 16603000 | J11: 16603000
A12: A11 | B12: info@meinberaterhaus.de | C12: Wer57fra# | D12: www.aigportal.de/hydra/#!/aig | E12: AIG Europe Limited (ex WÜBA)Angebot/Post | F12: 90017016989 | G12: B11 | H12: AIG Europe Limited (Marke WüBa) | I12: 16603000 | J12: 16603000
A13: A12 | E13: Allianz Leben | G13: B12 | H13: Allianz Leben | I13: 50/110/2650 | J13: 50/110/2650 | AF13: 72020435
A14: A13 | E14: Allianz Kranken | G14: B13 | H14: Allianz Kranken | I14: 705850637 | J14: 70/585/0637 | AF14: 72020435
A15: A14 | B15: GMAFXMX | C15: wer57fra | D15: über Zertifikat | E15: Allianz Sach | G15: B14 | H15: Allianz Sach | I15: 502062202 | J15: 50/110/1334 | AF15: 501100675 | AI15: 50/100/1003
A16: A15 | E16: Alte Leipziger Bauspar AG | G16: B15 | H16: Alte Leipziger Bauspar AG | J16: 5124 | AI16: 7170 | AJ16: 600028446
A17: A16 | B17: petri.w | C17: wer57fra | E17: Alte Leipziger | G17: B16 | H17: Alte Leipziger (Sach und Leben) | I17: 580678002 | J17: 580678001
A18: A17 | B18: info@meinberaterhaus.de | C18: Dbhisjs61* | E18: AMEX | G18: B17 | H18: Amex | J18: 55956 | AI18: 48794
A19: A18 | B19: info@meinberaterhaus.de | C19: Dbhisjstr61+ | E19: Ammerländer | F19: 1007096041001 | G19: B18 | H19: Ammerländer | I19: 24600 | J19: 24600
A20: A19 | B20: info@meinberaterhaus.de | C20: Dbhisjstr61+ | D20: VEMA | E20: Ammerländer | G20: B19 | H20: Ammerländer | I20: 24600
A21: A20 | B21: LM20000196 | C21: Dbhisjs61# | D21: https://www.aok.de/vp | E21: AOK Plus | G21: B20 | H21: AOK Plus | J21: LM20000196
A22: A21 | B22: 05065 | C22: 406324 | E22: Apella | G22: B21 | H22: Apella | J22: 05065 | AI22: 36328
A23: A22 | B23: 36328 | C23: Tommy22+ | E23: Apella | G23: B22 | H23: Apella
A24: A23 | B24: MP02723 | C24: Dbhsjs62 | E24: ARAG Krankenversicherungen | F24: 0000100628121 | G24: B23 | H24: ARAG Krankenversicherungen | I24: 60344 | J24: 643/060344
A25: A24 | B25: MP02723 | C25: Dbhsjs62 | E25: ARAG Rectsschutzversicherung | F25: 11005918075931 | G25: B24 | H25: ARAG Rechtsschutzversicherung | I25: AA2481-3 | J25: 643/AA2481-3 | L25: 7975101
A26: A25 | B26: MP02723 | C26: Dbhsjs62 | D26: https://www.arag-partnervertrieb.de/ | E26: ARAG | F26: 97733195 | G26: B25 | H26: ARAG Versicherungen | I26: AA2481-3 | J26: 643/AA2481-3
A27: A26 | B27: 89299 | C27: pacco2006 | E27: ASC | G27: B26 | H27: ASC | J27: 89299 | AI27: 71518
A28: A27 | B28: 4187038 | C28: Mein703? | E28: DeltaLloyd | G28: B27 | H28: Athora (alt Athene ;Delta Lloyd) | J28: 4187038 | AI28: 3958752
A29: A28 | B29: info@meinberaterhaus.de | C29: Wer57fra | E29: AUXILIA Rechtsschutz-Versicherungs AG | G29: B28 | H29: AUXILIA Rechtsschutz-Versicherungs AG | I29: 107175 | J29: 107175 | L29: 108980 | T29: 112366 | AI29: 107351
A30: A29 | E30: AXA (Innendienst) Kfz | G30: B29 | H30: AXA (Innendienst) Kfz | P30: 10/48/00/1783 | Q30: 10/48/00/1778
A31: A30 | E31: AXA Leben | G31: B30 | H31: AXA Leben | I31: 1035006249 | J31: 10/35/00/6249
A32: A31 | E32: AXA Leben (alt DBV-Leben) | G32: B31 | H32: AXA Leben (alt DBV-Leben) | J32: 10/36/00/2754
A33: A32 | B33: AXA30940 | C33: Dahlie13 | E33: AXA Sach | G33: B32 | H33: AXA Sach | I33: 1048000805, 1048001741, 1048001767, 1048001772, | J33: 10/48/00/0805 | O33: 11/48/00/8586 | P33: 10/48/00/1767 | Q33: 10/48/00/1741 | R33: 10/48/00/1772 | V33: 10/48/00/1791 | W33: 10/48/00/1296 | Y33: 10/48/00/1268 | Z33: 10/48/00/1674 | AA33: 10/48/00/1743 | AB33: 10/48/00/1190 | AI33: 10/48/00/3645
A34: A33 | E34: AXA Sach (Rahmenvertrag Kfz) | G34: B33 | H34: AXA Sach (Rahmenvertrag Kfz) | J34: 130040363
A35: A34 | E35: AXA Sach (Rahmenvertrag Sach) | G35: B34 | H35: AXA Sach (Rahmenvertrag Sach) | I35: 006548 | J35: 003816
A36: A35 | E36: AXA/DBV Kranken | G36: B35 | H36: AXA/DBV Kranken | I36: 5707000805 | J36: 5707000805 | AF36: 5707000376
A37: A36 | B37: 782644 | C37: uWybH3v6Ys | D37: über fbs / Zurich | E37: Zurich Sach / fbs (ex Baden-Badener) | G37: B36 | H37: Zurich Sach / fbs (ex Baden-Badener) | J37: 782644 | L37: 76993201
A38: A37 | B38: wer57fra | C38: d7ad19f6 | E38: Barmenia | G38: B37 | H38: Barmenia | I38: 0073/2556 | J38: 0073/2556 | L38: 0021/1695
A39: A38 | B39: 600688 | C39: !dBhiSjstr61! | D39: https://partner.basler-mietkaution.de/Account/LogOn?ReturnUrl=%2f | G39: B38 | H39: Baloise - Mietkaution | J39: 600688
A40: A39 | B40: info@meinberaterhaus.de | C40: ISdBH2020? | D40: www.basler-vertriebsservice.de | E40: Basler | G40: B39 | H40: Baloise Sachversicherung AG | I40: 082225 | J40: 600688
...

Sheet BÜ´s
A1: Mailadressen für Bestandsübertragungen | C1: Courtagekonten
C2: BeraterHaus | D2: VEMA | E2: Invers | F2: Maxpool | G2: Petri | H2: Röder | I2: Tippmann | J2: Hildebrandt | K2: Hesselbarth | L2: Hartkopf | M2: Sach | N2: kfz | O2: Leben | P2: Kranken
A3: AXA Sach | B3: Bestandsuebertragung-Makler@axa.de | G3: 1048001764 | M3: 10/48/00/0805 bzw. 003816 | N3: 130040363 | O3: 10/35/00/6249 | P3: 5707000805
A4: AXA Kfz | B4: Bestandsuebertragung-Makler@axa.de | G4: 1048001783
A5: AXA Leben | B5: Bestandsuebertragung-Makler@axa.de
A6: AXA Kranken | B6: Bestandsuebertragung-Makler@axa.de
A7: Allianz Sach | B7: amvb-uebertragung@allianz.de | M7: 50/110/1334
A8: Allianz Leben | B8: lebensversicherung@allianz.de | O8: 70/202/2262
A9: Allianz Kranken | B9: APKV-ZMSB-KUWU@allianz.de | P9: 70/585/0637
A10: Alte Leipziger Leben | B10: vertrieb@alte-leipziger.de
A11: Alte Leipziger Sach | B11: vertrieb@alte-leipziger.de
A12: ARAG | B12: bu-makler@arag.de
A13: Barmenia Versicherung | B13: md-leipzig@barmenia.de
A14: Die Bayerische | B14: provisionsreklamation@diebayerische.de
A15: Ergo | B15: maklerauftraege-b@ergo.de | M15: 886986 | O15: (H) 887884 (V) 886986
A16: Generali Sach | B16: gen-maklerauftrag@generali.de | C16: 122700 | G16: 103677 | M16: 122700 | N16: 293181 | O16: 122700 | P16: 122700
A17: Generali Kfz | C17: 122700 | G17: 103679
A18: Generali Leben
A19: Gothaer Leben | B19: lv_service@gothaer.de | C19: 691-2336
A20: Gothaer Kranken | B20: kv_service@gothaer.de
A21: Gothaer Sach | B21: gkc_mm@gothaer.de | C21: 28446
A22: Hanse-Merkur | B22: Heiko.Domigalle@hansemerkur.de | M22: 221/1200468 | O22: 221/1200468 | P22: 221/1200468
A23: Hallesche Kranken | B23: VTW-ZK-ZB@alte-leipziger.de
A24: HDI Leben | B24: leben.service@hdi.de | M24: 203-44780 | N24: 203166 | O24: 021449
A25: HDI Sach | B25: HK.Vertrag@hdi.de
A26: Invers | B26: bestandsuebertragung@invers-gruppe.de | C26: 7993201 | G26: 7993201-013 | M26: 7993201-xx
A27: Inter | B27: maklerservice@inter.de | E27: 568063
A28: Kravag | B28: G_Vertriebsverwaltung_Makler@ruv.de | N28: 770/771072
A29: LV 1871 | B29: florian.steinhilber@lv1871.de | O29: 23 288830
A30: Nürnberger Leben | B30: michael.hoffmann@nuernberger.de | C30: 152053992 | O30: 152/05/3992
A31: Nürnberger Sach | B31: Ronald.Schleicher@nuernberger.de | C31: 152053992 | M31: 152/05/3992 | P31: 152/05/3992
A32: Mannheimer | B32: mdleipzig@mannheimer.de | E32: 522/89456 | M32: 522/60720 | P32: 522/66982
A33: Maxpool
A34: Rhion Versicherung | B34: zva@rhion.de
A35: Signal | B35: maklerauftrag@signal-iduna.de | M35: 1370/02419
A36: Volkswohlbund | B36: kc-ost@volkswohl-bund.de | M36: 184/204 | O36: 184/204
A37: Württembergische | B37: mandatsbearbeitung@wuerttembergische.de | M37: 6810-7150-4 | N37: 6810-7151-2 | O37: 6850-5223-7
A39: ansonsten über Maklerbetreuer einreichen

Sheet Post
A1: Gesellschaft | B1: Art der Zustellung | C1: Zugang
A2: Advocard | C2: Briefpost
A3: Allianz | B3: AMS/Concenter | C3: Briefpost | E3: Doppelerfassung
A4: Alte Leipziger | B4: AMS/Concenter
A5: ASC | B5: AMS/Concenter
A6: AXA | B6: AMS/Concenter | C6: Briefpost | D6: Maklerportal | E6: nur csv
A7: Baden-Badener | B7: AMS/Concenter
A8: Barmenia | B8: Easy Login
A9: Basler | C9: Briefpost
A10: Canada Life | B10: Easy Login
A11: Concordia
A12: Condor | B12: über R+V
A13: Continentale | B13: AMS/Concenter | C13: Transferservice | D13: Easy-Login | E13: gdv
A14: die Bayerische | C14: Briefpost
A15: Direct Line | B15: E-Mail | C15: Portal
A16: DBV | B16: AMS/Concenter | C16: Briefpost
A17: Easy Login
A18: Generali | C18: Briefpost
A19: Gothaer | B19: AMS/Concenter
A20: Haftpflichtkasse | B20: AMS/Concenter
A21: Hanse Merkur | B21: E-Mail
A22: HDI | B22: AMS/Concenter | C22: Transferservice | D22: Easy-Login | E22: Doppelerfassung
A23: Helvetia | B23: E-Mail
A24: Ideal | B24: E-Mail
A25: Inter | B25: Extranet
A26: Interlloyd | B26: Extranet
A27: Interrisk | C27: Briefpost
A28: Invers | B28: Extranet
A29: Janitos | B29: Portal | C29: keine Briefpost
A30: KRAVAG | B30: AMS/Concenter | C30: Briefpost
A31: KS-Auxilia
A32: LV1871 | B32: AMS/Concenter | C32: Transferservice | D32: Easy-Login
A33: Nürnberger | B33: AMS/Concenter | E33: PDF; GDV
A34: R+V Versicherung | B34: AMS/Concenter | C34: Briefpost
A35: Rhion | B35: AMS/Concenter | E35: PDF
A36: Stuttgarter | B36: AMS/Concenter
A37: TGIC
A38: VEMA | B38: AMS/Concenter
A39: VHV
A40: Volkswohlbund | B40: AMS/Concenter | C40: Transferservice | D40: Easy-Login | E40: PDF
...

Sheet Einzel
A1: =+Passwörter_Agenturen!H1 -> Gesellschaft / Partner | B1: =+Passwörter_Agenturen!J1 -> BeraterHaus | C1: =+Passwörter_Agenturen!I1 -> VEMA | D1: =+Passwörter_Agenturen!K1 -> ASC | E1: =+Passwörter_Agenturen!L1 -> Invers | F1: =+Passwörter_Agenturen!N1 -> maxpool | G1: =+Passwörter_Agenturen!P1 -> Petri | H1: =+Passwörter_Agenturen!Q1 -> Tippmann | I1: =+Passwörter_Agenturen!R1 -> Röder | J1: =+Passwörter_Agenturen!S1 -> Hesselbarth | K1: =+Passwörter_Agenturen!T1 -> Furch | L1: =+Passwörter_Agenturen!U1 -> Hartkopf | M1: =+Passwörter_Agenturen!V1 -> Hildebrandt | N1: =+Passwörter_Agenturen!W1 -> Hollatz | ... Z1: =+Passwörter_Agenturen!AI1 -> Reif
A2: =+Passwörter_Agenturen!H2 -> AAB Augsburger Aktienbank (Invers) | B2: =+Passwörter_Agenturen!J2 -> 0 | C2: =+Passwörter_Agenturen!I2 -> 0 | D2: =+Passwörter_Agenturen!K2 -> 0 | E2: =+Passwörter_Agenturen!L2 -> 0 | F2: =+Passwörter_Agenturen!M2 -> 0 | G2: =+Passwörter_Agenturen!N2 -> 0 | H2: =+Passwörter_Agenturen!P2 -> 0 | I2: =+Passwörter_Agenturen!Q2 -> 0 | J2: =+Passwörter_Agenturen!R2 -> 0 | K2: =+Passwörter_Agenturen!S2 -> 0 | L2: =+Passwörter_Agenturen!T2 -> 0 | M2: =+Passwörter_Agenturen!U2 -> 0 | N2: =+Passwörter_Agenturen!V2 -> 0 | O2: =+Passwörter_Agenturen!W2 -> 0 | ... Z2: =+Passwörter_Agenturen!AH2 -> 0
A3: =+Passwörter_Agenturen!H4 -> abc-teleconsult | B3: =+Passwörter_Agenturen!J4 -> 0 | C3: =+Passwörter_Agenturen!I4 -> 0 | D3: =+Passwörter_Agenturen!K4 -> 0 | E3: =+Passwörter_Agenturen!L4 -> 0 | F3: =+Passwörter_Agenturen!M4 -> 0 | G3: =+Passwörter_Agenturen!N4 -> 0 | H3: =+Passwörter_Agenturen!P4 -> 0 | I3: =+Passwörter_Agenturen!Q4 -> 0 | J3: =+Passwörter_Agenturen!R4 -> 0 | K3: =+Passwörter_Agenturen!S4 -> 0 | L3: =+Passwörter_Agenturen!T4 -> 0 | M3: =+Passwörter_Agenturen!U4 -> 0 | N3: =+Passwörter_Agenturen!V4 -> 0 | O3: =+Passwörter_Agenturen!W4 -> 0 | ... Z3: =+Passwörter_Agenturen!AH4 -> 0
A4: =+Passwörter_Agenturen!H5 -> ACE European Group Limited Direktion für Deutschland | B4: =+Passwörter_Agenturen!J5 | C4: =+Passwörter_Agenturen!I5 -> 2202_VEMA | D4: =+Passwörter_Agenturen!K5 -> 0 | E4: =+Passwörter_Agenturen!L5 -> 0 | F4: =+Passwörter_Agenturen!M5 -> 0 | G4: =+Passwörter_Agenturen!N5 -> 0 | H4: =+Passwörter_Agenturen!P5 -> 0 | I4: =+Passwörter_Agenturen!Q5 -> 0 | J4: =+Passwörter_Agenturen!R5 -> 0 | K4: =+Passwörter_Agenturen!S5 -> 0 | L4: =+Passwörter_Agenturen!T5 -> 0 | M4: =+Passwörter_Agenturen!U5 -> 0 | N4: =+Passwörter_Agenturen!V5 -> 0 | O4: =+Passwörter_Agenturen!W5 -> 0 | ... Z4: =+Passwörter_Agenturen!AH5 -> 0
A5: =+Passwörter_Agenturen!H6 -> Adcuri | B5: =+Passwörter_Agenturen!J6 -> 950086739 | C5: =+Passwörter_Agenturen!I6 -> 950212022 | D5: =+Passwörter_Agenturen!K6 -> 0 | E5: =+Passwörter_Agenturen!L6 -> 0 | F5: =+Passwörter_Agenturen!M6 -> 0 | G5: =+Passwörter_Agenturen!N6 -> 0 | H5: =+Passwörter_Agenturen!P6 -> 0 | I5: =+Passwörter_Agenturen!Q6 -> 0 | J5: =+Passwörter_Agenturen!R6 -> 0 | K5: =+Passwörter_Agenturen!S6 -> 0 | L5: =+Passwörter_Agenturen!T6 -> 0 | M5: =+Passwörter_Agenturen!U6 -> 0 | N5: =+Passwörter_Agenturen!V6 -> 0 | O5: =+Passwörter_Agenturen!W6 -> 0 | ... Z5: =+Passwörter_Agenturen!AH6 -> 0
A6: =+Passwörter_Agenturen!H8 -> Adcuri (VEMA) | B6: =+Passwörter_Agenturen!J8 -> 950205963 alt | C6: =+Passwörter_Agenturen!I8 -> 950212022 | D6: =+Passwörter_Agenturen!K8 -> 0 | E6: =+Passwörter_Agenturen!L8 -> 0 | F6: =+Passwörter_Agenturen!M8 -> 0 | G6: =+Passwörter_Agenturen!N8 -> 0 | H6: =+Passwörter_Agenturen!P8 -> 0 | I6: =+Passwörter_Agenturen!Q8 -> 0 | J6: =+Passwörter_Agenturen!R8 -> 0 | K6: =+Passwörter_Agenturen!S8 -> 0 | L6: =+Passwörter_Agenturen!T8 -> 0 | M6: =+Passwörter_Agenturen!U8 -> 0 | N6: =+Passwörter_Agenturen!V8 -> 0 | O6: =+Passwörter_Agenturen!W8 -> 0 | ... Z6: =+Passwörter_Agenturen!AH8 -> 0
A7: =+Passwörter_Agenturen!H9 -> Advigon (ex CSS 80002841) | B7: =+Passwörter_Agenturen!J9 -> 3780145 | C7: =+Passwörter_Agenturen!I9 -> 3780145 | D7: =+Passwörter_Agenturen!K9 -> 0 | E7: =+Passwörter_Agenturen!L9 -> 0 | F7: =+Passwörter_Agenturen!M9 -> 0 | G7: =+Passwörter_Agenturen!N9 -> 0 | H7: =+Passwörter_Agenturen!P9 -> 0 | I7: =+Passwörter_Agenturen!Q9 -> 0 | J7: =+Passwörter_Agenturen!R9 -> 0 | K7: =+Passwörter_Agenturen!S9 -> 0 | L7: =+Passwörter_Agenturen!T9 -> 0 | M7: =+Passwörter_Agenturen!U9 -> 0 | N7: =+Passwörter_Agenturen!V9 -> 0 | O7: =+Passwörter_Agenturen!W9 -> 0 | ... Z7: =+Passwörter_Agenturen!AH9 -> 0
A8: =+Passwörter_Agenturen!H10 -> AdvoCard (Dialog) | B8: =+Passwörter_Agenturen!J10 -> 70/5523/00122700 | C8: =+Passwörter_Agenturen!I10 -> 106151 | D8: =+Passwörter_Agenturen!K10 -> 0 | E8: =+Passwörter_Agenturen!L10 -> 0 | F8: =+Passwörter_Agenturen!M10 -> 0 | G8: =+Passwörter_Agenturen!N10 -> 0 | H8: =+Passwörter_Agenturen!P10 -> 590/5509 | I8: =+Passwörter_Agenturen!Q10 -> 0 | J8: =+Passwörter_Agenturen!R10 -> 0 | K8: =+Passwörter_Agenturen!S10 -> 0 | L8: =+Passwörter_Agenturen!T10 -> 0 | M8: =+Passwörter_Agenturen!U10 -> 0 | N8: =+Passwörter_Agenturen!V10 -> 0 | O8: =+Passwörter_Agenturen!W10 -> 0 | ... Z8: =+Passwörter_Agenturen!AH10 -> 0
A9: =+Passwörter_Agenturen!#REF! -> #REF! | B9: =+Passwörter_Agenturen!#REF! -> #REF! | C9: =+Passwörter_Agenturen!#REF! -> #REF! | D9: =+Passwörter_Agenturen!#REF! -> #REF! | E9: =+Passwörter_Agenturen!#REF! -> #REF! | F9: =+Passwörter_Agenturen!#REF! -> #REF! | G9: =+Passwörter_Agenturen!#REF! -> #REF! | H9: =+Passwörter_Agenturen!#REF! -> #REF! | ... Z9: =+Passwörter_Agenturen!#REF! -> #REF!
A10: =+Passwörter_Agenturen!H12 -> AIG Europe Limited (Marke WüBa) | B10: =+Passwörter_Agenturen!J12 -> 16603000 | C10: =+Passwörter_Agenturen!I12 -> 16603000 | D10: =+Passwörter_Agenturen!K12 -> 0 | E10: =+Passwörter_Agenturen!L12 -> 0 | F10: =+Passwörter_Agenturen!M12 -> 0 | G10: =+Passwörter_Agenturen!N12 -> 0 | H10: =+Passwörter_Agenturen!P12 -> 0 | I10: =+Passwörter_Agenturen!Q12 -> 0 | J10: =+Passwörter_Agenturen!R12 -> 0 | K10: =+Passwörter_Agenturen!S12 -> 0 | L10: =+Passwörter_Agenturen!T12 -> 0 | M10: =+Passwörter_Agenturen!U12 -> 0 | N10: =+Passwörter_Agenturen!V12 -> 0 | O10: =+Passwörter_Agenturen!W12 -> 0 | ... Z10: =+Passwörter_Agenturen!AH12 -> 0
A11: =+Passwörter_Agenturen!H13 -> Allianz Leben | B11: =+Passwörter_Agenturen!J13 -> 50/110/2650 | C11: =+Passwörter_Agenturen!I13 -> 50/110/2650 | D11: =+Passwörter_Agenturen!K13 -> 0 | E11: =+Passwörter_Agenturen!L13 -> 0 | F11: =+Passwörter_Agenturen!M13 -> 0 | G11: =+Passwörter_Agenturen!N13 -> 0 | H11: =+Passwörter_Agenturen!P13 -> 0 | I11: =+Passwörter_Agenturen!Q13 -> 0 | J11: =+Passwörter_Agenturen!R13 -> 0 | K11: =+Passwörter_Agenturen!S13 -> 0 | L11: =+Passwörter_Agenturen!T13 -> 0 | M11: =+Passwörter_Agenturen!U13 -> 0 | N11: =+Passwörter_Agenturen!V13 -> 0 | O11: =+Passwörter_Agenturen!W13 -> 0 | ... Z11: =+Passwörter_Agenturen!AH13 -> 0
A12: =+Passwörter_Agenturen!H14 -> Allianz Kranken | B12: =+Passwörter_Agenturen!J14 -> 70/585/0637 | C12: =+Passwörter_Agenturen!I14 -> 705850637 | D12: =+Passwörter_Agenturen!K14 -> 0 | E12: =+Passwörter_Agenturen!L14 -> 0 | F12: =+Passwörter_Agenturen!M14 -> 0 | G12: =+Passwörter_Agenturen!N14 -> 0 | H12: =+Passwörter_Agenturen!P14 -> 0 | I12: =+Passwörter_Agenturen!Q14 -> 0 | J12: =+Passwörter_Agenturen!R14 -> 0 | K12: =+Passwörter_Agenturen!S14 -> 0 | L12: =+Passwörter_Agenturen!T14 -> 0 | M12: =+Passwörter_Agenturen!U14 -> 0 | N12: =+Passwörter_Agenturen!V14 -> 0 | O12: =+Passwörter_Agenturen!W14 -> 0 | ... Z12: =+Passwörter_Agenturen!AH14 -> 0
A13: =+Passwörter_Agenturen!H16 -> Alte Leipziger Bauspar AG | B13: =+Passwörter_Agenturen!J16 -> 5124 | C13: =+Passwörter_Agenturen!I16 -> 0 | D13: =+Passwörter_Agenturen!K16 -> 0 | E13: =+Passwörter_Agenturen!L16 -> 0 | F13: =+Passwörter_Agenturen!M16 -> 0 | G13: =+Passwörter_Agenturen!N16 -> 0 | H13: =+Passwörter_Agenturen!P16 -> 0 | I13: =+Passwörter_Agenturen!Q16 -> 0 | J13: =+Passwörter_Agenturen!R16 -> 0 | K13: =+Passwörter_Agenturen!S16 -> 0 | L13: =+Passwörter_Agenturen!T16 -> 0 | M13: =+Passwörter_Agenturen!U16 -> 0 | N13: =+Passwörter_Agenturen!V16 -> 0 | O13: =+Passwörter_Agenturen!W16 -> 0 | ... Z13: =+Passwörter_Agenturen!AH16 -> 0
A14: =+Passwörter_Agenturen!H18 -> Amex | B14: =+Passwörter_Agenturen!J18 -> 55956 | C14: =+Passwörter_Agenturen!I18 -> 0 | D14: =+Passwörter_Agenturen!K18 -> 0 | E14: =+Passwörter_Agenturen!L18 -> 0 | F14: =+Passwörter_Agenturen!M18 -> 0 | G14: =+Passwörter_Agenturen!N18 -> 0 | H14: =+Passwörter_Agenturen!P18 -> 0 | I14: =+Passwörter_Agenturen!Q18 -> 0 | J14: =+Passwörter_Agenturen!R18 -> 0 | K14: =+Passwörter_Agenturen!S18 -> 0 | L14: =+Passwörter_Agenturen!T18 -> 0 | M14: =+Passwörter_Agenturen!U18 -> 0 | N14: =+Passwörter_Agenturen!V18 -> 0 | O14: =+Passwörter_Agenturen!W18 -> 0 | ... Z14: =+Passwörter_Agenturen!AH18 -> 0
A15: =+Passwörter_Agenturen!H19 -> Ammerländer | B15: =+Passwörter_Agenturen!J19 -> 24600 | C15: =+Passwörter_Agenturen!I19 -> 24600 | D15: =+Passwörter_Agenturen!K19 -> 0 | E15: =+Passwörter_Agenturen!L19 -> 0 | F15: =+Passwörter_Agenturen!M19 -> 0 | G15: =+Passwörter_Agenturen!N19 -> 0 | H15: =+Passwörter_Agenturen!P19 -> 0 | I15: =+Passwörter_Agenturen!Q19 -> 0 | J15: =+Passwörter_Agenturen!R19 -> 0 | K15: =+Passwörter_Agenturen!S19 -> 0 | L15: =+Passwörter_Agenturen!T19 -> 0 | M15: =+Passwörter_Agenturen!U19 -> 0 | N15: =+Passwörter_Agenturen!V19 -> 0 | O15: =+Passwörter_Agenturen!W19 -> 0 | ... Z15: =+Passwörter_Agenturen!AH19 -> 0
A16: =+Passwörter_Agenturen!H20 -> Ammerländer | B16: =+Passwörter_Agenturen!J20 -> 0 | C16: =+Passwörter_Agenturen!I20 -> 24600 | D16: =+Passwörter_Agenturen!K20 -> 0 | E16: =+Passwörter_Agenturen!L20 -> 0 | F16: =+Passwörter_Agenturen!M20 -> 0 | G16: =+Passwörter_Agenturen!N20 -> 0 | H16: =+Passwörter_Agenturen!P20 -> 0 | I16: =+Passwörter_Agenturen!Q20 -> 0 | J16: =+Passwörter_Agenturen!R20 -> 0 | K16: =+Passwörter_Agenturen!S20 -> 0 | L16: =+Passwörter_Agenturen!T20 -> 0 | M16: =+Passwörter_Agenturen!U20 -> 0 | N16: =+Passwörter_Agenturen!V20 -> 0 | O16: =+Passwörter_Agenturen!W20 -> 0 | ... Z16: =+Passwörter_Agenturen!AH20 -> 0
A17: =+Passwörter_Agenturen!H22 -> Apella | B17: =+Passwörter_Agenturen!J22 -> 05065 | C17: =+Passwörter_Agenturen!I22 -> 0 | D17: =+Passwörter_Agenturen!K22 -> 0 | E17: =+Passwörter_Agenturen!L22 -> 0 | F17: =+Passwörter_Agenturen!M22 -> 0 | G17: =+Passwörter_Agenturen!N22 -> 0 | H17: =+Passwörter_Agenturen!P22 -> 0 | I17: =+Passwörter_Agenturen!Q22 -> 0 | J17: =+Passwörter_Agenturen!R22 -> 0 | K17: =+Passwörter_Agenturen!S22 -> 0 | L17: =+Passwörter_Agenturen!T22 -> 0 | M17: =+Passwörter_Agenturen!U22 -> 0 | N17: =+Passwörter_Agenturen!V22 -> 0 | O17: =+Passwörter_Agenturen!W22 -> 0 | ... Z17: =+Passwörter_Agenturen!AH22 -> 0
A18: =+Passwörter_Agenturen!H23 -> Apella | B18: =+Passwörter_Agenturen!J23 -> 0 | C18: =+Passwörter_Agenturen!I23 -> 0 | D18: =+Passwörter_Agenturen!K23 -> 0 | E18: =+Passwörter_Agenturen!L23 -> 0 | F18: =+Passwörter_Agenturen!M23 -> 0 | G18: =+Passwörter_Agenturen!N23 -> 0 | H18: =+Passwörter_Agenturen!P23 -> 0 | I18: =+Passwörter_Agenturen!Q23 -> 0 | J18: =+Passwörter_Agenturen!R23 -> 0 | K18: =+Passwörter_Agenturen!S23 -> 0 | L18: =+Passwörter_Agenturen!T23 -> 0 | M18: =+Passwörter_Agenturen!U23 -> 0 | N18: =+Passwörter_Agenturen!V23 -> 0 | O18: =+Passwörter_Agenturen!W23 -> 0 | ... Z18: =+Passwörter_Agenturen!AH23 -> 0
A19: =+Passwörter_Agenturen!H24 -> ARAG Krankenversicherungen | B19: =+Passwörter_Agenturen!J24 -> 643/060344 | C19: =+Passwörter_Agenturen!I24 -> 60344 | D19: =+Passwörter_Agenturen!K24 -> 0 | E19: =+Passwörter_Agenturen!L24 -> 0 | F19: =+Passwörter_Agenturen!M24 -> 0 | G19: =+Passwörter_Agenturen!N24 -> 0 | H19: =+Passwörter_Agenturen!P24 -> 0 | I19: =+Passwörter_Agenturen!Q24 -> 0 | J19: =+Passwörter_Agenturen!R24 -> 0 | K19: =+Passwörter_Agenturen!S24 -> 0 | L19: =+Passwörter_Agenturen!T24 -> 0 | M19: =+Passwörter_Agenturen!U24 -> 0 | N19: =+Passwörter_Agenturen!V24 -> 0 | O19: =+Passwörter_Agenturen!W24 -> 0 | ... Z19: =+Passwörter_Agenturen!AH24 -> 0
A20: =+Passwörter_Agenturen!H25 -> ARAG Rechtsschutzversicherung | B20: =+Passwörter_Agenturen!J25 -> 643/AA2481-3 | C20: =+Passwörter_Agenturen!I25 -> AA2481-3 | D20: =+Passwörter_Agenturen!K25 -> 0 | E20: =+Passwörter_Agenturen!L25 -> 7975101 | F20: =+Passwörter_Agenturen!M25 -> 0 | G20: =+Passwörter_Agenturen!N25 -> 0 | H20: =+Passwörter_Agenturen!P25 -> 0 | I20: =+Passwörter_Agenturen!Q25 -> 0 | J20: =+Passwörter_Agenturen!R25 -> 0 | K20: =+Passwörter_Agenturen!S25 -> 0 | L20: =+Passwörter_Agenturen!T25 -> 0 | M20: =+Passwörter_Agenturen!U25 -> 0 | N20: =+Passwörter_Agenturen!V25 -> 0 | O20: =+Passwörter_Agenturen!W25 -> 0 | ... Z20: =+Passwörter_Agenturen!AH25 -> 0
A21: =+Passwörter_Agenturen!H26 -> ARAG Versicherungen | B21: =+Passwörter_Agenturen!J26 -> 643/AA2481-3 | C21: =+Passwörter_Agenturen!I26 -> AA2481-3 | D21: =+Passwörter_Agenturen!K26 -> 0 | E21: =+Passwörter_Agenturen!L26 -> 0 | F21: =+Passwörter_Agenturen!M26 -> 0 | G21: =+Passwörter_Agenturen!N26 -> 0 | H21: =+Passwörter_Agenturen!P26 -> 0 | I21: =+Passwörter_Agenturen!Q26 -> 0 | J21: =+Passwörter_Agenturen!R26 -> 0 | K21: =+Passwörter_Agenturen!S26 -> 0 | L21: =+Passwörter_Agenturen!T26 -> 0 | M21: =+Passwörter_Agenturen!U26 -> 0 | N21: =+Passwörter_Agenturen!V26 -> 0 | O21: =+Passwörter_Agenturen!W26 -> 0 | ... Z21: =+Passwörter_Agenturen!AH26 -> 0
A22: =+Passwörter_Agenturen!H27 -> ASC | B22: =+Passwörter_Agenturen!J27 -> 89299 | C22: =+Passwörter_Agenturen!I27 -> 0 | D22: =+Passwörter_Agenturen!K27 -> 0 | E22: =+Passwörter_Agenturen!L27 -> 0 | F22: =+Passwörter_Agenturen!M27 -> 0 | G22: =+Passwörter_Agenturen!N27 -> 0 | H22: =+Passwörter_Agenturen!P27 -> 0 | I22: =+Passwörter_Agenturen!Q27 -> 0 | J22: =+Passwörter_Agenturen!R27 -> 0 | K22: =+Passwörter_Agenturen!S27 -> 0 | L22: =+Passwörter_Agenturen!T27 -> 0 | M22: =+Passwörter_Agenturen!U27 -> 0 | N22: =+Passwörter_Agenturen!V27 -> 0 | O22: =+Passwörter_Agenturen!W27 -> 0 | ... Z22: =+Passwörter_Agenturen!AH27 -> 0
A23: =+Passwörter_Agenturen!H28 -> Athora (alt Athene ;Delta Lloyd) | B23: =+Passwörter_Agenturen!J28 -> 4187038 | C23: =+Passwörter_Agenturen!I28 -> 0 | D23: =+Passwörter_Agenturen!K28 -> 0 | E23: =+Passwörter_Agenturen!L28 -> 0 | F23: =+Passwörter_Agenturen!M28 -> 0 | G23: =+Passwörter_Agenturen!N28 -> 0 | H23: =+Passwörter_Agenturen!P28 -> 0 | I23: =+Passwörter_Agenturen!Q28 -> 0 | J23: =+Passwörter_Agenturen!R28 -> 0 | K23: =+Passwörter_Agenturen!S28 -> 0 | L23: =+Passwörter_Agenturen!T28 -> 0 | M23: =+Passwörter_Agenturen!U28 -> 0 | N23: =+Passwörter_Agenturen!V28 -> 0 | O23: =+Passwörter_Agenturen!W28 -> 0 | ... Z23: =+Passwörter_Agenturen!AH28 -> 0
A24: =+Passwörter_Agenturen!H29 -> AUXILIA Rechtsschutz-Versicherungs AG | B24: =+Passwörter_Agenturen!J29 -> 107175 | C24: =+Passwörter_Agenturen!I29 -> 107175 | D24: =+Passwörter_Agenturen!K29 -> 0 | E24: =+Passwörter_Agenturen!L29 -> 108980 | F24: =+Passwörter_Agenturen!M29 -> 0 | G24: =+Passwörter_Agenturen!N29 -> 0 | H24: =+Passwörter_Agenturen!P29 -> 0 | I24: =+Passwörter_Agenturen!Q29 -> 0 | J24: =+Passwörter_Agenturen!R29 -> 0 | K24: =+Passwörter_Agenturen!S29 -> 0 | L24: =+Passwörter_Agenturen!T29 -> 112366 | M24: =+Passwörter_Agenturen!U29 -> 0 | N24: =+Passwörter_Agenturen!V29 -> 0 | O24: =+Passwörter_Agenturen!W29 -> 0 | ... Z24: =+Passwörter_Agenturen!AH29 -> 0
A25: =+Passwörter_Agenturen!H30 -> AXA (Innendienst) Kfz | B25: =+Passwörter_Agenturen!J30 -> 0 | C25: =+Passwörter_Agenturen!I30 -> 0 | D25: =+Passwörter_Agenturen!K30 -> 0 | E25: =+Passwörter_Agenturen!L30 -> 0 | F25: =+Passwörter_Agenturen!M30 -> 0 | G25: =+Passwörter_Agenturen!N30 -> 0 | H25: =+Passwörter_Agenturen!P30 -> 10/48/00/1783 | I25: =+Passwörter_Agenturen!Q30 -> 10/48/00/1778 | J25: =+Passwörter_Agenturen!R30 -> 0 | K25: =+Passwörter_Agenturen!S30 -> 0 | L25: =+Passwörter_Agenturen!T30 -> 0 | M25: =+Passwörter_Agenturen!U30 -> 0 | N25: =+Passwörter_Agenturen!V30 -> 0 | O25: =+Passwörter_Agenturen!W30 -> 0 | ... Z25: =+Passwörter_Agenturen!AH30 -> 0
A26: =+Passwörter_Agenturen!H31 -> AXA Leben | B26: =+Passwörter_Agenturen!J31 -> 10/35/00/6249 | C26: =+Passwörter_Agenturen!I31 -> 1035006249 | D26: =+Passwörter_Agenturen!K31 -> 0 | E26: =+Passwörter_Agenturen!L31 -> 0 | F26: =+Passwörter_Agenturen!M31 -> 0 | G26: =+Passwörter_Agenturen!N31 -> 0 | H26: =+Passwörter_Agenturen!P31 -> 0 | I26: =+Passwörter_Agenturen!Q31 -> 0 | J26: =+Passwörter_Agenturen!R31 -> 0 | K26: =+Passwörter_Agenturen!S31 -> 0 | L26: =+Passwörter_Agenturen!T31 -> 0 | M26: =+Passwörter_Agenturen!U31 -> 0 | N26: =+Passwörter_Agenturen!V31 -> 0 | O26: =+Passwörter_Agenturen!W31 -> 0 | ... Z26: =+Passwörter_Agenturen!AH31 -> 0
A27: =+Passwörter_Agenturen!H32 -> AXA Leben (alt DBV-Leben) | B27: =+Passwörter_Agenturen!J32 -> 10/36/00/2754 | C27: =+Passwörter_Agenturen!I32 -> 0 | D27: =+Passwörter_Agenturen!K32 -> 0 | E27: =+Passwörter_Agenturen!L32 -> 0 | F27: =+Passwörter_Agenturen!M32 -> 0 | G27: =+Passwörter_Agenturen!N32 -> 0 | H27: =+Passwörter_Agenturen!P32 -> 0 | I27: =+Passwörter_Agenturen!Q32 -> 0 | J27: =+Passwörter_Agenturen!R32 -> 0 | K27: =+Passwörter_Agenturen!S32 -> 0 | L27: =+Passwörter_Agenturen!T32 -> 0 | M27: =+Passwörter_Agenturen!U32 -> 0 | N27: =+Passwörter_Agenturen!V32 -> 0 | O27: =+Passwörter_Agenturen!W32 -> 0 | ... Z27: =+Passwörter_Agenturen!AH32 -> 0
A28: =+Passwörter_Agenturen!H33 -> AXA Sach | B28: =+Passwörter_Agenturen!J33 -> 10/48/00/0805 | C28: =+Passwörter_Agenturen!I33 -> 1048000805, 1048001741, 1048001767, 1048001772, | D28: =+Passwörter_Agenturen!K33 -> 0 | E28: =+Passwörter_Agenturen!L33 -> 0 | F28: =+Passwörter_Agenturen!M33 -> 0 | G28: =+Passwörter_Agenturen!N33 -> 0 | H28: =+Passwörter_Agenturen!P33 -> 10/48/00/1767 | I28: =+Passwörter_Agenturen!Q33 -> 10/48/00/1741 | J28: =+Passwörter_Agenturen!R33 -> 10/48/00/1772 | K28: =+Passwörter_Agenturen!S33 -> 0 | L28: =+Passwörter_Agenturen!T33 -> 0 | M28: =+Passwörter_Agenturen!U33 -> 0 | N28: =+Passwörter_Agenturen!V33 -> 10/48/00/1791 | O28: =+Passwörter_Agenturen!W33 -> 10/48/00/1296 | ... Z28: =+Passwörter_Agenturen!AH33 -> 0
A29: =+Passwörter_Agenturen!H34 -> AXA Sach (Rahmenvertrag Kfz) | B29: =+Passwörter_Agenturen!J34 -> 130040363 | C29: =+Passwörter_Agenturen!#REF! -> #REF! | D29: =+Passwörter_Agenturen!K34 -> 0 | E29: =+Passwörter_Agenturen!L34 -> 0 | F29: =+Passwörter_Agenturen!M34 -> 0 | G29: =+Passwörter_Agenturen!N34 -> 0 | H29: =+Passwörter_Agenturen!P34 -> 0 | I29: =+Passwörter_Agenturen!Q34 -> 0 | J29: =+Passwörter_Agenturen!R34 -> 0 | K29: =+Passwörter_Agenturen!S34 -> 0 | L29: =+Passwörter_Agenturen!T34 -> 0 | M29: =+Passwörter_Agenturen!U34 -> 0 | N29: =+Passwörter_Agenturen!V34 -> 0 | O29: =+Passwörter_Agenturen!W34 -> 0 | ... Z29: =+Passwörter_Agenturen!AH34 -> 0
A30: =+Passwörter_Agenturen!H35 -> AXA Sach (Rahmenvertrag Sach) | B30: =+Passwörter_Agenturen!J35 -> 003816 | C30: =+Passwörter_Agenturen!I34 -> 0 | D30: =+Passwörter_Agenturen!K35 -> 0 | E30: =+Passwörter_Agenturen!L35 -> 0 | F30: =+Passwörter_Agenturen!M35 -> 0 | G30: =+Passwörter_Agenturen!N35 -> 0 | H30: =+Passwörter_Agenturen!P35 -> 0 | I30: =+Passwörter_Agenturen!Q35 -> 0 | J30: =+Passwörter_Agenturen!R35 -> 0 | K30: =+Passwörter_Agenturen!S35 -> 0 | L30: =+Passwörter_Agenturen!T35 -> 0 | M30: =+Passwörter_Agenturen!U35 -> 0 | N30: =+Passwörter_Agenturen!V35 -> 0 | O30: =+Passwörter_Agenturen!W35 -> 0 | ... Z30: =+Passwörter_Agenturen!AH35 -> 0
A31: =+Passwörter_Agenturen!H37 -> Zurich Sach / fbs (ex Baden-Badener) | B31: =+Passwörter_Agenturen!J37 -> 782644 | C31: =+Passwörter_Agenturen!I37 -> 0 | D31: =+Passwörter_Agenturen!K37 -> 0 | E31: =+Passwörter_Agenturen!L37 -> 76993201 | F31: =+Passwörter_Agenturen!M37 -> 0 | G31: =+Passwörter_Agenturen!N37 -> 0 | H31: =+Passwörter_Agenturen!P37 -> 0 | I31: =+Passwörter_Agenturen!Q37 -> 0 | J31: =+Passwörter_Agenturen!R37 -> 0 | K31: =+Passwörter_Agenturen!S37 -> 0 | L31: =+Passwörter_Agenturen!T37 -> 0 | M31: =+Passwörter_Agenturen!U37 -> 0 | N31: =+Passwörter_Agenturen!V37 -> 0 | O31: =+Passwörter_Agenturen!W37 -> 0 | ... Z31: =+Passwörter_Agenturen!AH37 -> 0
A32: =+Passwörter_Agenturen!H41 -> Baloise Lebensversicherung AG | B32: =+Passwörter_Agenturen!J41 -> 871/0929 | C32: =+Passwörter_Agenturen!I41 -> 871/0929 | D32: =+Passwörter_Agenturen!K41 -> 0 | E32: =+Passwörter_Agenturen!L41 -> 0 | F32: =+Passwörter_Agenturen!M41 -> 0 | G32: =+Passwörter_Agenturen!N41 -> 0 | H32: =+Passwörter_Agenturen!P41 -> 0 | I32: =+Passwörter_Agenturen!Q41 -> 0 | J32: =+Passwörter_Agenturen!R41 -> 0 | K32: =+Passwörter_Agenturen!S41 -> 0 | L32: =+Passwörter_Agenturen!T41 -> 0 | M32: =+Passwörter_Agenturen!U41 -> 0 | N32: =+Passwörter_Agenturen!V41 -> 0 | O32: =+Passwörter_Agenturen!W41 -> 0 | ... Z32: =+Passwörter_Agenturen!AH41 -> 0
A33: =+Passwörter_Agenturen!H42 -> BSG Baloise Service GmbH | B33: =+Passwörter_Agenturen!J42 -> 0 | C33: =+Passwörter_Agenturen!I42 -> 2202-00 | D33: =+Passwörter_Agenturen!K42 -> 0 | E33: =+Passwörter_Agenturen!L42 -> 0 | F33: =+Passwörter_Agenturen!M42 -> 0 | G33: =+Passwörter_Agenturen!N42 -> 0 | H33: =+Passwörter_Agenturen!P42 -> 0 | I33: =+Passwörter_Agenturen!Q42 -> 0 | J33: =+Passwörter_Agenturen!R42 -> 0 | K33: =+Passwörter_Agenturen!S42 -> 0 | L33: =+Passwörter_Agenturen!T42 -> 0 | M33: =+Passwörter_Agenturen!U42 -> 0 | N33: =+Passwörter_Agenturen!V42 -> 0 | O33: =+Passwörter_Agenturen!W42 -> 0 | ... Z33: =+Passwörter_Agenturen!AH42 -> 0
A34: =+Passwörter_Agenturen!H44 -> Bayerische Hausbesitzer Versicherung | B34: =+Passwörter_Agenturen!J44 -> 6255 | C34: =+Passwörter_Agenturen!I44 -> 6255 | D34: =+Passwörter_Agenturen!K44 -> 0 | E34: =+Passwörter_Agenturen!L44 -> 0 | F34: =+Passwörter_Agenturen!M44 -> 0 | G34: =+Passwörter_Agenturen!N44 -> 0 | H34: =+Passwörter_Agenturen!P44 -> 0 | I34: =+Passwörter_Agenturen!Q44 -> 0 | J34: =+Passwörter_Agenturen!R44 -> 0 | K34: =+Passwörter_Agenturen!S44 -> 0 | L34: =+Passwörter_Agenturen!T44 -> 0 | M34: =+Passwörter_Agenturen!U44 -> 0 | N34: =+Passwörter_Agenturen!V44 -> 0 | O34: =+Passwörter_Agenturen!W44 -> 0 | ... Z34: =+Passwörter_Agenturen!AH44 -> 0
A35: =+Passwörter_Agenturen!#REF! -> #REF! | B35: =+Passwörter_Agenturen!#REF! -> #REF! | C35: =+Passwörter_Agenturen!#REF! -> #REF! | D35: =+Passwörter_Agenturen!#REF! -> #REF! | E35: =+Passwörter_Agenturen!#REF! -> #REF! | F35: =+Passwörter_Agenturen!#REF! -> #REF! | G35: =+Passwörter_Agenturen!#REF! -> #REF! | H35: =+Passwörter_Agenturen!#REF! -> #REF! | ... Z35: =+Passwörter_Agenturen!#REF! -> #REF!
A36: =+Passwörter_Agenturen!H46 -> BHW (Invers) | B36: =+Passwörter_Agenturen!J46 -> 0 | C36: =+Passwörter_Agenturen!I46 -> 0 | D36: =+Passwörter_Agenturen!K46 -> 0 | E36: =+Passwörter_Agenturen!L46 -> 02431917357 | F36: =+Passwörter_Agenturen!M46 -> 0 | G36: =+Passwörter_Agenturen!N46 -> 0 | H36: =+Passwörter_Agenturen!P46 -> 0 | I36: =+Passwörter_Agenturen!Q46 -> 0 | J36: =+Passwörter_Agenturen!R46 -> 0 | K36: =+Passwörter_Agenturen!S46 -> 0 | L36: =+Passwörter_Agenturen!T46 -> 0 | M36: =+Passwörter_Agenturen!U46 -> 0 | N36: =+Passwörter_Agenturen!V46 -> 0 | O36: =+Passwörter_Agenturen!W46 -> 0 | ... Z36: =+Passwörter_Agenturen!AH46 -> 0
A37: =+Passwörter_Agenturen!H47 -> BKM Bausparkasse Mainz | B37: =+Passwörter_Agenturen!J47 -> 568063 | C37: =+Passwörter_Agenturen!I47 -> 0 | D37: =+Passwörter_Agenturen!K47 -> 0 | E37: =+Passwörter_Agenturen!L47 -> 0 | F37: =+Passwörter_Agenturen!M47 -> 0 | G37: =+Passwörter_Agenturen!N47 -> 0 | H37: =+Passwörter_Agenturen!P47 -> 0 | I37: =+Passwörter_Agenturen!Q47 -> 0 | J37: =+Passwörter_Agenturen!R47 -> 0 | K37: =+Passwörter_Agenturen!S47 -> 0 | L37: =+Passwörter_Agenturen!T47 -> 0 | M37: =+Passwörter_Agenturen!U47 -> 0 | N37: =+Passwörter_Agenturen!V47 -> 0 | O37: =+Passwörter_Agenturen!W47 -> 0 | ... Z37: =+Passwörter_Agenturen!AH47 -> 0
A38: =+Passwörter_Agenturen!H48 -> Brandgilde Versicherung | B38: =+Passwörter_Agenturen!J48 -> 14356 | C38: =+Passwörter_Agenturen!I48 -> 0 | D38: =+Passwörter_Agenturen!K48 -> 0 | E38: =+Passwörter_Agenturen!L48 -> 0 | F38: =+Passwörter_Agenturen!M48 -> 0 | G38: =+Passwörter_Agenturen!N48 -> 0 | H38: =+Passwörter_Agenturen!P48 -> 0 | I38: =+Passwörter_Agenturen!Q48 -> 0 | J38: =+Passwörter_Agenturen!R48 -> 0 | K38: =+Passwörter_Agenturen!S48 -> 0 | L38: =+Passwörter_Agenturen!T48 -> 0 | M38: =+Passwörter_Agenturen!U48 -> 0 | N38: =+Passwörter_Agenturen!V48 -> 0 | O38: =+Passwörter_Agenturen!W48 -> 0 | ... Z38: =+Passwörter_Agenturen!AH48 -> 0
A39: =+Passwörter_Agenturen!H49 -> Canada Life | B39: =+Passwörter_Agenturen!J49 -> A5G6 | C39: =+Passwörter_Agenturen!I49 -> A5G6 | D39: =+Passwörter_Agenturen!K49 -> 0 | E39: =+Passwörter_Agenturen!L49 -> 0 | F39: =+Passwörter_Agenturen!M49 -> 0 | G39: =+Passwörter_Agenturen!N49 -> 0 | H39: =+Passwörter_Agenturen!P49 -> 0 | I39: =+Passwörter_Agenturen!Q49 -> 0 | J39: =+Passwörter_Agenturen!R49 -> 0 | K39: =+Passwörter_Agenturen!S49 -> 0 | L39: =+Passwörter_Agenturen!T49 -> 0 | M39: =+Passwörter_Agenturen!U49 -> 0 | N39: =+Passwörter_Agenturen!V49 -> 0 | O39: =+Passwörter_Agenturen!W49 -> 0 | ... Z39: =+Passwörter_Agenturen!AH49 -> 0
A40: =+Passwörter_Agenturen!H50 -> Care Concept | B40: =+Passwörter_Agenturen!J50 -> 000 20 50000 | C40: =+Passwörter_Agenturen!I50 -> 0 | D40: =+Passwörter_Agenturen!K50 -> 0 | E40: =+Passwörter_Agenturen!L50 -> 0 | F40: =+Passwörter_Agenturen!M50 -> 0 | G40: =+Passwörter_Agenturen!N50 -> 0 | H40: =+Passwörter_Agenturen!P50 -> 0 | I40: =+Passwörter_Agenturen!Q50 -> 0 | J40: =+Passwörter_Agenturen!R50 -> 0 | K40: =+Passwörter_Agenturen!S50 -> 0 | L40: =+Passwörter_Agenturen!T50 -> 0 | M40: =+Passwörter_Agenturen!U50 -> 0 | N40: =+Passwörter_Agenturen!V50 -> 0 | O40: =+Passwörter_Agenturen!W50 -> 0 | ... Z40: =+Passwörter_Agenturen!AH50 -> 0
...

Sheet VEMA-Nr´n
A1: Vermittlernummern (alle Versicherer) Stand: 13.01.2017
A2: Versicherer | B2: VmNr | C2: Attribute
A3: Aachener Bausparkasse AG
A4: ACE European Group Limited Direktion für Deutschland | B4: 2202_VEMA | C4: keine Anbindung (VR)
A5: Adcuri | B5: 950212022
A6: Advigon Versicherung AG | B6: 3780145 | C6: Zuordnung bestätigt
A7: Aegon Niederlassung Deutschland der Aegon Ireland plc
A8: AIG Europe Limited (Marke WüBa) | B8: 16603-000 | C8: Zuordnung bestätigt
A9: ALLCURA Versicherungs-Aktiengesellschaft
A10: Allianz Versicherungen | B10: 0603123 | C10: Zuordnung bestätigt _x000D_ _x000D_ KV
A11: Allianz Versicherungen | B11: 2202_VEMA | C11: keine Anbindung (VR) _x000D_ Sach
A12: Allianz Versicherungen | B12: 501102650 | C12: Zuordnung bestätigt _x000D_ LV
A13: Allianz Versicherungen | B13: 702022262 | C13: Zuordnung bestätigt _x000D_ _x000D_ _x000D_ CZ beendet (VM) _x000D_ LV
A14: Allianz Versicherungen | B14: 705850637 | C14: Zuordnung bestätigt _x000D_ KV
A15: Allianz Esa cargo & logistics GmbH
A16: Allianz Global Assistance
A17: ALTE LEIPZIGER | B17: 580678001 | C17: nicht zugeordnet _x000D_ LV _x000D_ Sach
A18: ALTE LEIPZIGER | B18: 580678002 | C18: Verbundnummer
A19: Alte Oldenburger Krankenversicherung AG
A20: Amlin Insurance SE Direktion für Deutschland
A21: Ammerländer Versicherung VVaG | B21: 24600 | C21: Zuordnung bestätigt
A22: ANGLO Underwriting GmbH
A23: ARAG Versicherungen | B23: 2202_VEMA | C23: keine Anbindung (VR)
A24: Atradius Kreditversicherung
A25: AUXILIA Rechtsschutz-Versicherungs AG | B25: 107175 | C25: Zuordnung bestätigt
A26: AUXILIA Rechtsschutz-Versicherungs AG | B26: 112366 | C26: Zuordnung bestätigt _x000D_ _x000D_ _x000D_ CZ beendet (VM)
A27: AXA Versicherungen | B27: 1035006249 | C27: nicht zugeordnet _x000D_ LV
A28: AXA Versicherungen | B28: 1048000805 | C28: Zuordnung bestätigt _x000D_ _x000D_ Sach
A29: AXA Versicherungen | B29: 1048001741 | C29: nicht für Neugeschäft _x000D_ Sach
A30: AXA Versicherungen | B30: 1048001767 | C30: nicht für Neugeschäft _x000D_ Sach
A31: AXA Versicherungen | B31: 1048001772 | C31: nicht für Neugeschäft _x000D_ Sach
A32: AXA Versicherungen | B32: 1048001791 | C32: nicht für Neugeschäft _x000D_ Sach
A33: AXA Versicherungen | B33: 5707000805 | C33: nicht zugeordnet _x000D_ KV
A34: Baden-Badener Versicherung AG | B34: 782644 | C34: Zuordnung bestätigt
A35: Baloise Luxembourg
A36: Barmenia | B36: 0021/1650 | C36: nicht zugeordnet
A37: Basler Versicherungen | B37: 082225 | C37: Zuordnung bestätigt
A38: BavariaDirekt OVAG - Ostdeutsche Versicherung Aktiengesellschaft
A39: Bayerische Hausbesitzer-Versicherungs-Gesellschaft a.G. | B39: 6255 | C39: Zuordnung bestätigt
A40: Berliner Versicherung (BVAG)
...

Sheet Invers interne Nr´n
A1: Kurz. | B1: Anbieter | C1: Vermittler-Nr beim Anb.
A2: AAB | B2: Augsburger Aktienbank | C2: 9900133692
A3: ADC | B3: ADCURI | C3: 950094925
A4: ALTSA | B4: Alte Leipziger Sachversicherung | C4: 130656.466 Sach-Nr. 22-2409
A5: AUX | B5: Auxilia | C5: 108980
A6: AXASA | B6: AXA Sachversicherung | C6: 1036008206
A7: BAD | B7: Baden Badener | C7: 76993201
A8: BARKV | B8: Barmenia Versicherungen | C8: 0021/1695
A9: BASSA | B9: Basler Versicherungen | C9: 621-285
A10: BAYSA | B10: Bayerische Sachversicherung | C10: 090124
A11: CCOSA | B11: Concordia Versicherungsgesellschaft a.G. | C11: 55280-055
A12: DEURAG | B12: DEURAG Rechtsschutz AG | C12: 51089
... A39: ZURLV | B39: Zurich Deutscher Herold Lebensversicherung AG | C39: 222963

Sheet Frank Malzahn
A1: Adressenliste und Anmeldungen online
A3: Gesellschaft | B3: Adresse | C3: Telefon/Fax | D3: Verm.-Nr. | E3: Benutzer | F3: Passwort | G3: Internet-Adr.
A5: Apella AG | E5: 36809 | F5: 942876 | G5: www.apella.de
A9: Amex | E9: AX40464 | F9: 101045 | G9: www.amex-online.de
A12: Alte Leipziger AG | B12: Alte Leipziger Platz 1 | D12: 827053.001 Verb. VNR | E12: Malzahn.F | F12: 160568 | G12: www.al-vermittler.de
B13: 61440 Oberursel | D13: 23-9855 Frank Sach
E14: Malzahn.E | F14: 191108
A17: ARAG | B17: ARAG Platz 1 | C17: T 0211 9890 1616 | D17: 565/28214 | G17: www.arag.de
B18: 40472 Düsseldorf | C18: F 0211 963 2850
A20: AXA Versicherung AG | B20: Colonia Allee 10-20 | D20: 80/36/00/0462 Frank | E20: AXA35986 | F20: Katharina1 | G20: www.axa.de
B21: 51067 Köln | D21: 80/36/00/0633 Elke | F21: (auch für sichere Nachrichten)
A24: Baden Badener | D24: 77005410 | E24: 77005410 | F24: g2ihANUHC4 | G24: www.bb-maklerwelt.de.
A30: Bayerische | B30: Thomas-Dehler-Str-. 25 | C30: 0180 1228366 | D30: 6801 581213 Frank | E30: MAK581213-0001 | F30: FrankMal1 | G30: www.bbv.de
B31: 81737 München | D31: 6801 580370 Elke | E31: MAK580370-0001 | F31: FrankMal1
A34: Condor | B34: Admiralitätsstr. 67 | C34: T 040 36139 0 | D34: 78468 | E34: 78468 | F34: Katharina1 | G34: www.condor-versicherungsgruppe.de
B35: 20459 Hamburg | C35: F 040 36139-100 | E35: Anmeldung R+V
A38: Concordia | D38: 55197 | E38: 55197000 | F38: Cordial01 | G38: www.concordia.de
G40: Login allg.
A41: DEURAG | B41: Die Freiheit 14 | C41: T 0561/780061 | D41: 21003 | E41: 21003 | F41: FrankM | G41: www.rs.deurag.de
B42: 34117 Kassel | C42: F 0561 102973 | F42: Benutzer: malzahn | G42: www.deurag.de
F43: Passw.:KatharinaHe1 (31.5.16) | G43: für GDV-Download
E45: 9111984 | F45: bu3c#kH7 | G45: www.deutscherring-kranken-makler.de
A46: Deutscher Ring | B46: Ludwig-Erhard-Str. 22 | C46: T 040 3599-50 | D46: 5315/0001 | E46: Antr.-Bausparen(Begleitz.)
B47: 20459 Hamburg | C47: F 040 3599-5128 | E47: über Apella
D48: Sicherheitsfrage:
A49: easyLogin | C49: 0921 75758 555 | D49: Katharina Heußer | E49: vb027300880 | F49: FrankM | G49: www.easy-login.de
D50: Antw.: 13.06.1962
E51: Benutzername GDV | F51: FrankMal01 (08.01.2018)
A52: ERGO / Victoria | B52: Stresemannstr. 111 | C52: 030 88781- | E52: OM_V173043_MaFr | G52: www.makler-ergo.de
B53: 10963 Berlin | F53: PIN 2412 | G53: www.datenbereitstellung.de
E54: E843589
D55: 135886
A56: Generali | B56: Adenauer Ring 7-11 | C56: 01803 284666 | D56: 156902 | E56: Alias:FrankMal1 | F56: Sommer2018 | G56: www.maklernet.generali.de
B57: 81737 München | D57: für GDV-Daten | E57: G156902A | F57: FrankMal1 | G57: www.generali.de
A59: Gothaer | D59: 28269 | E59: V103059 | F59: Frank12M | G59: www.makler.gothaer.de
C61: Herr Lang
A62: Haftpflichtkasse Darmstadt | B62: Postfach 11 26 | C62: T 06154 601-1356 | D62: 009530-525
B63: 64373 Roßdorf | C63: F 06154/601-2356
A66: HDI | B66: Postfach 101 625 | C66: 0221 144 3001 | D66: 257544 | E66: 257544HDI | F66: AnnettWer18 | G66: www.mymaklernet.de
B67: 50456 Köln | C67: 0221 144 61975 | E67: fzf3nkf8 | F67: 42013
...

Sheet Tabelle1
