Workbook
Name Z_4076B397_909E_4026_BE11_525A508BFFEA_.wvu.Cols: Einzel!$D:$Y

Sheet RennsteigFinanz
A1: lfd.Nr. A | B1: Benutzername/Maklernummer | C1: Passwort | D1: Sonstiges | E1: Gesellschaft | F1: Schreibweise | G1: lfd.Nr.B | H1: Gesellschaft / Partner | I1: VEMA | J1: RennsteigFINANZ | K1: Reif | L1: Malzahn | M1: Tippmann | N1: Jung DMS | O1: Invers | P1: AMEX Pool
A2: A1 | B2: ZHQ28EM | C2: RFmrt2026AZ. | D2: Zertifikat: af1A1Kpy | E2: Allianz Leben | G2: B1 | H2: Allianz Leben | I2: 40/101/1458 | J2: 40/101/1458
A3: A2 | B3: ZHQ28EM | C3: RFmrt2026AZ. | D3: Zertifikat: rQhwEebr | E3: Allianz Kranken | G3: B2 | H3: Allianz Kranken | I3: 70/585/5190 | J3: 70/585/5190
A4: A3 | B4: ZHQ28EM | C4: RFmrt2026AZ. | D4: Zertifikat: af1A1Kpy | E4: Allianz Sach | G4: B3 | H4: Allianz Sach | I4: 50/206/5317 | J4: 50/112/0119 | K4: 50/112/0119 | L4: 50/206/5317 | M4: 50/206/5317
A5: A4 | B5: Tippmann.V | C5: RF2024Ti | G5: B4 | H5: Alte Leipziger (Leben) | I5: 5317 | J5: 151915001 | K5: 151915001 | L5: 151915002
A6: A5 | B6: Tippmann.V | C6: RF2024Ti | G6: B5 | H6: Alte Leipziger (Sach) | I6: 5317 | J6: 151915001
A7: A6 | B7: Tippmann.V | C7: RF2024Ti | G7: B6 | H7: Alte Leipziger Bauspar AG | I7: 5317 | J7: 151915002
A8: A7 | B8: info@rennsteigfinanz.de | C8: RFmrt2024. | G8: B7 | H8: AMEX | J8: 56988
A9: A8 | G9: B8 | H9: AOK Plus
A10: A9 | B10: 39946 | C10: ApellA2025+ | D10: Postbox VEMA | E10: Apella | G10: B9 | H10: Apella | J10: 39946
A11: A10 | B11: 39946 | C11: RFmrt2026. | D11: 2-Faktor auf info@... | E11: Apella | G11: B10 | H11: Apella | J11: 39946 | K11: 36328
A12: A11 | B12: A246252 | C12: RFmrt2024. | G12: B11 | H12: AXA Leben | I12: 2836005064 | J12: 2836005064 | K12: 2836005164 | L12: 2836005264 | M12: 2836005364
A13: A12 | B13: A246252 | C13: RFmrt2024. | G13: B12 | H13: AXA Sach | I13: 2836005064 | J13: 2836005064 | K13: 2836005164 | L13: 2836005264 | M13: 2836005364
A14: A13 | B14: A246252 | C14: RFmrt2024. | G14: B13 | H14: AXA/DBV Kranken | I14: 2836005064 | J14: 2836005064 | K14: 2836005164 | L14: 2836005264 | M14: 2836005364
A15: A14 | B15: 185903 | D15: easy Login | E15: Baloise Lebensversicherung AG | G15: B14 | H15: Baloise Lebensversicherung AG | I15: 871/4137 | J15: 871/4137
A16: A15 | B16: 185903 | D16: easy Login | E16: Baloise Sachversicherung | G16: B15 | H16: Baloise Sachversicherung AG | I16: 085125
A17: A16 | B17: 185903 | D17: easy Login | E17: Basler Service GmbH | G17: B16 | H17: BSG Baloise Service GmbH | I17: VEMA-5317-00 | K17: VEMA-5317-01 | L17: VEMA-5317-02 | M17: VEMA-5317-03
A18: A17 | B18: B8C2-Tip | C18: Tip_B8C2 | D18: Zertifikat / easy Login | G18: B17 | H18: Canada Life | J18: B8C2
A19: A18 | C19: info@rennsteigfinanz | D19: RF2025cg. | G19: B18 | H19: Carglass | J19: 7048103
A20: A19 | B20: info@rennsteigfinanz.de | C20: dd022ba5-4482-4691-a782-f5907919a4c1 | D20: Con center Schnittstelle zur Datenabholung AMEX | G20: B19 | H20: Con Center
A21: A20 | B21: 38907000 | C21: Kolpin6150 | E21: Kranken/Komposit/Sonsige/BHW-Bausparen | G21: B20 | H21: Concordia | I21: 38907/000 | J21: 38907/000 | K21: 38907/001 | L21: 38907/002 | M21: 38907/003
A22: A21 | B22: RMP0S25 | C22: R+V2024RF | G22: B21 | H22: Condor Sach (nur Altbestand)
A23: A22 | G23: B22 | H23: Continentale Lebensversicherung (Invers) | O23: 7605304
A24: A23 | B24: 5914912039 | C24: GNqHHQDAC58gjhOQVaPPAYzmmkj8mphB | G24: B23 | H24: covomo (BiPRO Datenabholung) | I24: 5914912039
A25: A24 | B25: 5914912039 | C25: RFmrt2024! | D25: VEMA-Sprungziel | G25: B24 | H25: Covomo Vertriebsportal | I25: 5914912039
A26: A25 | C26: RYS1928 | G26: B25 | H26: DATEV | J26: 1568922
A27: A26 | C27: VT24Datev | G27: B26 | H27: DATEV Smart Login
A28: A27 | C28: FM24Datev | G28: B27 | H28: DATEV Smart Login
A29: A28 | B29: 706967 | C29: vcP9MtRCw7Sf61 | D29: Postkorb | G29: B28 | H29: Dialog Lebensversicherung-AG | J29: 706967
A30: A29 | B30: USGRAVXL | C30: Rf2026.dS | G30: B29 | H30: Dialog Versicherung AG (Sach+Proxalto) | I30: 707036 | J30: 707005 | K30: 707054 | L30: 707055 | M30: 707056 | P30: 707058
A31: A30 | B31: 009542-389 | C31: TUQRRTIAED | G31: B30 | H31: Die Haftpflichtkasse Darmstadt | I31: 009542-389 | K31: 009542-667 | L31: 009542-668 | M31: 009542-669
A32: A31 | G32: B31 | H32: DKB
A33: A32 | B33: VEMA5317 | D33: https://office.domcura.de | E33: Domcura AG | G33: B32 | H33: Domcura AG | I33: VEMA5317
A34: A33 | B34: 6643764265 | C34: RFmrT2024!#%2024 | G34: B33 | H34: easy Login | J34: 6643764265
A35: A34 | B35: Administrator | C35: ELO24admin | D35: installer/installeR24 | G35: B34 | H35: ELO
A36: A35 | B36: Tippmann | C36: ELO24VT | G36: B35 | H36: ELO
A37: A36 | B37: Malzahn | C37: ELO24FM | G37: B36 | H37: ELO
A38: A37 | B38: Reif | C38: ELO24TR | G38: B37 | H38: ELO
A39: A38 | B39: Hesselbarth | C39: ELO24FH | G39: B38 | H39: ELO
A40: A39 | G40: B39 | H40: Europa Lebensversicherung (Invers) | O40: 9409649
...

Sheet Favoriten
A1: Gesellschaften | B1: Werner | C1: Volker | D1: Hans Jürgen | E1: Frank M. | F1: Frank H. | G1: Tommy | H1: Abrechnungen
A2: Aachener Bausparkasse | C2: x | E2: x
A3: abc-teleconsult
A4: ACE European Group Limited Direktion für Deutschland
A5: AdvoCard (Generali)
A6: Allianz Sach | B6: x | C6: x | D6: x | E6: x | G6: x
A7: Deutsche Lebensversicherung AG (Allianz) | B7: x | E7: x
A8: Allianz Leben | B8: x | C8: x | D8: x | E8: x | F8: X
A9: Allianz Kranken | B9: x
A10: Alte Leipziger Sach und Leben | B10: x | C10: x | E10: x | G10: x
A11: Alte Leipziger Bauspar AG | C11: x | E11: x | G11: x
A12: Ammerländer | B12: x | E12: x | G12: x
A13: Amex | E13: (X)
A14: AOK Plus | B14: x | C14: x | G14: x
A15: ARAG Versicherungen | C15: x | G15: x
A16: ARAG Krankenversicherungen
A17: ARAG Rectsschutzversicherung | B17: x | C17: x | D17: x
A18: ASC
A19: Apella | E19: (x)
A20: HDI (Aspecta)
A21: AUXILIA Rechtsschutz-Versicherungs AG | B21: x | C21: x | E21: x | G21: x
A22: AAB Augsburger Aktienbank (Invers)
A23: AXA/DBV Kranken | B23: x | C23: x | D23: x | E23: xx
A24: Baden-Badener | C24: x | G24: x | H24: Zurich
A25: Barmenia | B25: x | C25: x | D25: x
A26: Adcuri | B26: x | C26: x | G26: x
A27: Basler (Sach) | B27: x | C27: x | D27: x | G27: x
A28: Basler Lebensversicherung AG | B28: x
A29: Basler Service GmbH | B29: x | C29: x | D29: x | E29: x
A30: BKM Bausparkasse Mainz | C30: x | G30: x
A31: BCA
A32: die Bayerische (ex BBV) | B32: x | C32: x | E32: x | G32: x
A33: BHW (Invers) | C33: x
A34: Brandgilde Versicherung | B34: x | D34: x
A35: Canada Life | B35: x | C35: x | D35: x | G35: x
A36: carglass | B36: x | C36: x | G36: x
A37: Care Concept | C37: x | D37: x | E37: x
A38: Concordia | B38: x | C38: x | D38: x | G38: x
A39: Condor Klass. LV/BU / Optima
A40: Condor Leben (FLV) / Optima | D40: x | E40: x | F40: X
...

Sheet Tools
A1: Firma | B1: Name | C1: Registrierungspaßwort | D1: Benutzername | E1: Paßwort | F1: Sonstiges | G1: Web-Zugang | H1: Ansprechpartner
A2: Zurich | B2: Beratungsnavigator | C2: Navigator3.0 | D2: werner.petri@meinberaterhaus.de | E2: Wer57fra$ | G2: www.mach-plus-mit-protection.de | H2: Zurich, Herr Patrick Wiertz, 0228 / 268 25 23 / patrick.wiertz@zurich.com
A3: BKM Bausparkasse Mainz | B3: KIS | D3: 9900056806314 | E3: 2FifpLSg | F3: Zertifikat | G3: https://kunden.bkm.de/cas/login? | H3: Herr Schäfer
A4: VHV | B4: MAXX-Net
A5: VHV | B5: VHV-Tarife
A6: Concordia | B6: COPRA
A7: Easy Login (Web) | B7: Easy-Versicherungsportale-Login | D7: EL11827 | E7: wer57fra | F7: Token | G7: www.easy-login.de
A8: Easy Login | B8: Easy-Client | D8: EL11827 | E8: wer57fra | F8: Token
A9: ELBE (Online) SdV | B9: ELBE | D9: 205703 | E9: kugecufa891 | G9: https://www.plan25.de/login.elbe
A10: Franke & Bornberg | B10: fb-beraterwelt (ex fb-xpert) | D10: petri | E10: vowe2014
A11: HDI | B11: Firmen Digital | G11: https://www.hdi.de/apps
A12: Ideenwerk
A13: Interrisk
A14: Kassensuche GmbH | B14: gesetzlichkrankenkassen.de | D14: WernerPetri | E14: 98527 | F14: 2356 | G14: www.makleraktiv.de
A15: R+V | B15: R+V Connect | D15: rom0s2s | E15: Wer57fra
A16: DATEV
A17: Versicherungsmarkt | B17: VM-Connect
A18: BCA | B18: BusinessPlus
A19: Procheck24 | D19: petri | E19: sonne
A20: Rhion
A21: Invers | B21: IMA
A22: Inveda | B22: IMA-Sync
A23: ASC | B23: ASC-Easy
A24: NAFI | B24: NAFI-Web
A25: SEB | B25: SEB-App | D25: BeraterHaus | E25: F31309H11
A26: Inveda | B26: IMA | D26: verwaltung@beraterhaus | E26: wer57fra
A27: SdV | B27: Schutzvereinigung der Vermittler | D27: SDV-20.902 | E27: 5GJBBp | G27: https://sdv-online.de/
A28: BauFinex | B28: Finanzierungsplattform | D28: volker-tippmann-7961 | E28: Dbhisjs61& | G28: https://www.baufinex.de/marktplatz/
A29: Starpool | B29: Finanzierungsplattform | D29: volker_tippmann | E29: Starpool$1 | G29: www.starpool.de
A30: Dr. Klein (Kreher) | B30: Finanzierungsplattform | E30: MBH2020! | G30: http://cloud.drklein.de/index.php/s/XN2J4YLngxiEXGY
A31: MSC Fondskonzept | B31: Investmentplattform
A32: Google-Kalender | B32: Web-Browser / Google / Kalenender | D32: dasberaterhaus@gmail.com | E32: Berater&Co. | G32: https://calendar.google.com/calendar/u/0/r/week
A34: BeraterHaus INTERN
A35: VEMA | B35: Paßwortverwaltung Makler-Extranets
A36: Fritz!Box | B36: Benutzer | D36: Volker | E36: persönlich erfragen
D37: Alex | E37: persönlich erfragen
A38: Server | B38: Zentrale | D38: buerO24 | E38: persönlich erfragen
A39: PC-Netzwerk | B39: Innendienst 1 | E39: buero2009
B40: Innendienst 2 | E40: buero2009
B41: Innendienst 3 | E41: buero2009
...

Sheet ex BH PW
A1: lfd.Nr. A | B1: Benutzername/Maklernummer | C1: Passwort | D1: Sonstiges | E1: Gesellschaft | F1: Schreibweise | G1: lfd.Nr.B | H1: Gesellschaft / Partner | I1: VEMA | J1: BeraterHaus | K1: ASC | L1: Invers | M1: Jung DMS | N1: maxpool | O1: AMEX | P1: Petri | Q1: Tippmann | R1: Röder | S1: Hesselbarth | T1: Furch | U1: Hartkopf | V1: Hildebrandt | W1: Hollatz | X1: Hopf | Y1: Kramer | Z1: Schellhorn | AA1: Lins | AB1: Littig | AC1: Lobe | AD1: Scharlach | AE1: Weißkopf | AF1: Schumacher | AG1: Autohaus Hüther | AH1: Motorrad Henkel | AI1: Reif | AJ1: Malzahn
A2: A1 | B2: 900426758302016 | C2: wer57fra | E2: AAB Augsburger Aktienbank | G2: B1 | H2: AAB Augsburger Aktienbank (Invers)
A3: A2 | E3: Aachener Bausparkasse | G3: B2 | H3: Aachener Bausparkasse | J3: 100015718 | AI3: Kroschwald / Invers
A4: A3 | E4: abc-teleconsult | G4: B3 | H4: abc-teleconsult | AI4: 20052
A5: A4 | E5: ACE European Group Limited Direktion für Deutschland | G5: B4 | H5: ACE European Group Limited Direktion für Deutschland | I5: 2202_VEMA | AI5: 71518
A6: A5 | B6: 950086739 | C6: wer57fra | E6: Adcuri | G6: B5 | H6: Adcuri | I6: 950212022 | J6: 950086739
A7: A6 | B7: 950094925 | C7: 7305ba3d | E7: Adcuri | G7: B6 | H7: Adcuri (Invers) | L7: 950094925
A8: A7 | B8: 950212022 | C8: BHSidJS61 | E8: Adcuri | G8: B7 | H8: Adcuri (VEMA) | I8: 950212022 | J8: 950205963 alt
A9: A8 | B9: info@suhlfinanz.de | C9: wer57fra | E9: CSS | G9: B8 | H9: Advigon (ex CSS 80002841) | I9: 3780145 | J9: 3780145
A10: A9 | E10: AdvoCard (Generali) | G10: B9 | H10: AdvoCard (Dialog) | I10: 106151 | J10: 70/5523/00122700 | P10: 590/5509
A11: A10 | B11: berat1pt | C11: ISdBH61Jstr | D11: Maklerportal | E11: AIG (ex WÜBA) | F11: 90017016989 | G11: B10 | H11: AIG Europe Limited (Marke WüBa) | I11: 16603000 | J11: 16603000
A12: A11 | B12: info@meinberaterhaus.de | C12: Wer57fra# | D12: www.aigportal.de/hydra/#!/aig | E12: AIG Europe Limited (ex WÜBA)Angebot/Post | F12: 90017016989 | G12: B11 | H12: AIG Europe Limited (Marke WüBa) | I12: 16603000 | J12: 16603000
A13: A12 | E13: Allianz Leben | G13: B12 | H13: Allianz Leben | I13: 50/110/2650 | J13: 50/110/2650 | AF13: 72020435
A14: A13 | E14: Allianz Kranken | G14: B13 | H14: Allianz Kranken | I14: 705850637 | J14: 70/585/0637 | AF14: 72020435
A15: A14 | B15: GMAFXMX | C15: wer57fra | D15: über Zertifikat | E15: Allianz Sach | G15: B14 | H15: Allianz Sach | I15: 502062202 | J15: 50/110/1334 | AF15: 501100675 | AI15: 50/100/1003
A16: A15 | E16: Alte Leipziger Bauspar AG | G16: B15 | H16: Alte Leipziger Bauspar AG | J16: 5124 | AI16: 7170 | AJ16: 600028446
A17: A16 | B17: petri.w | C17: wer57fra | E17: Alte Leipziger | G17: B16 | H17: Alte Leipziger (Sach und Leben) | I17: 580678002 | J17: 580678001
A18: A17 | B18: info@meinberaterhaus.de | C18: Dbhisjs61* | E18: AMEX | G18: B17 | H18: Amex | J18: 55956 | AI18: 48794
A19: A18 | B19: info@meinberaterhaus.de | C19: Dbhisjstr61+ | E19: Ammerländer | F19: 1007096041001 | G19: B18 | H19: Ammerländer | I19: 24600 | J19: 24600
A20: A19 | B20: info@meinberaterhaus.de | C20: Dbhisjstr61+ | D20: VEMA | E20: Ammerländer | G20: B19 | H20: Ammerländer | I20: 24600
A21: A20 | B21: LM20000196 | C21: Dbhisjs61# | D21: https://www.aok.de/vp | E21: AOK Plus | G21: B20 | H21: AOK Plus | J21: LM20000196
A22: A21 | B22: 05065 | C22: 406324 | E22: Apella | G22: B21 | H22: Apella | J22: 05065 | AI22: 36328
A23: A22 | B23: 36328 | C23: Tommy22+ | E23: Apella | G23: B22 | H23: Apella
A24: A23 | B24: MP02723 | C24: Dbhsjs62 | E24: ARAG Krankenversicherungen | F24: 0000100628121 | G24: B23 | H24: ARAG Krankenversicherungen | I24: 60344 | J24: 643/060344
A25: A24 | B25: MP02723 | C25: Dbhsjs62 | E25: ARAG Rectsschutzversicherung | F25: 11005918075931 | G25: B24 | H25: ARAG Rechtsschutzversicherung | I25: AA2481-3 | J25: 643/AA2481-3 | L25: 7975101
A26: A25 | B26: MP02723 | C26: Dbhsjs62 | D26: https://www.arag-partnervertrieb.de/ | E26: ARAG | F26: 97733195 | G26: B25 | H26: ARAG Versicherungen | I26: AA2481-3 | J26: 643/AA2481-3
A27: A26 | B27: 89299 | C27: pacco2006 | E27: ASC | G27: B26 | H27: ASC | J27: 89299 | AI27: 71518
A28: A27 | B28: 4187038 | C28: Mein703? | E28: DeltaLloyd | G28: B27 | H28: Athora (alt Athene ;Delta Lloyd) | J28: 4187038 | AI28: 3958752
A29: A28 | B29: info@meinberaterhaus.de | C29: Wer57fra | E29: AUXILIA Rechtsschutz-Versicherungs AG | G29: B28 | H29: AUXILIA Rechtsschutz-Versicherungs AG | I29: 107175 | J29: 107175 | L29: 108980 | T29: 112366 | AI29: 107351
A30: A29 | E30: AXA (Innendienst) Kfz | G30: B29 | H30: AXA (Innendienst) Kfz | P30: 10/48/00/1783 | Q30: 10/48/00/1778
A31: A30 | E31: AXA Leben | G31: B30 | H31: AXA Leben | I31: 1035006249 | J31: 10/35/00/6249
A32: A31 | E32: AXA Leben (alt DBV-Leben) | G32: B31 | H32: AXA Leben (alt DBV-Leben) | J32: 10/36/00/2754
A33: A32 | B33: AXA30940 | C33: Dahlie13 | E33: AXA Sach | G33: B32 | H33: AXA Sach | I33: 1048000805, 1048001741, 1048001767, 1048001772, | J33: 10/48/00/0805 | O33: 11/48/00/8586 | P33: 10/48/00/1767 | Q33: 10/48/00/1741 | R33: 10/48/00/1772 | V33: 10/48/00/1791 | W33: 10/48/00/1296 | Y33: 10/48/00/1268 | Z33: 10/48/00/1674 | AA33: 10/48/00/1743 | AB33: 10/48/00/1190 | AI33: 10/48/00/3645
A34: A33 | E34: AXA Sach (Rahmenvertrag Kfz) | G34: B33 | H34: AXA Sach (Rahmenvertrag Kfz) | J34: 130040363
A35: A34 | E35: AXA Sach (Rahmenvertrag Sach) | G35: B34 | H35: AXA Sach (Rahmenvertrag Sach) | I35: 006548 | J35: 003816
A36: A35 | E36: AXA/DBV Kranken | G36: B35 | H36: AXA/DBV Kranken | I36: 5707000805 | J36: 5707000805 | AF36: 5707000376
A37: A36 | B37: 782644 | C37: uWybH3v6Ys | D37: über fbs / Zurich | E37: Zurich Sach / fbs (ex Baden-Badener) | G37: B36 | H37: Zurich Sach / fbs (ex Baden-Badener) | J37: 782644 | L37: 76993201
A38: A37 | B38: wer57fra | C38: d7ad19f6 | E38: Barmenia | G38: B37 | H38: Barmenia | I38: 0073/2556 | J38: 0073/2556 | L38: 0021/1695
A39: A38 | B39: 600688 | C39: !dBhiSjstr61! | D39: https://partner.basler-mietkaution.de/Account/LogOn?ReturnUrl=%2f | G39: B38 | H39: Baloise - Mietkaution | J39: 600688
A40: A39 | B40: info@meinberaterhaus.de | C40: ISdBH2020? | D40: www.basler-vertriebsservice.de | E40: Basler | G40: B39 | H40: Baloise Sachversicherung AG | I40: 082225 | J40: 600688
...

Sheet BÜ´s
A1: Mailadressen für Bestandsübertragungen | C1: Courtagekonten
C2: BeraterHaus | D2: VEMA | E2: Invers | F2: Maxpool | G2: Petri | H2: Röder | I2: Tippmann | J2: Hildebrandt | K2: Hesselbarth | L2: Hartkopf | M2: Sach | N2: kfz | O2: Leben | P2: Kranken
A3: AXA Sach | B3: Bestandsuebertragung-Makler@axa.de | G3: 1048001764 | M3: 10/48/00/0805 bzw. 003816 | N3: 130040363 | O3: 10/35/00/6249 | P3: 5707000805
A4: AXA Kfz | B4: Bestandsuebertragung-Makler@axa.de | G4: 1048001783
A5: AXA Leben | B5: Bestandsuebertragung-Makler@axa.de
A6: AXA Kranken | B6: Bestandsuebertragung-Makler@axa.de
A7: Allianz Sach | B7: amvb-uebertragung@allianz.de | M7: 50/110/1334
A8: Allianz Leben | B8: lebensversicherung@allianz.de | O8: 70/202/2262
A9: Allianz Kranken | B9: APKV-ZMSB-KUWU@allianz.de | P9: 70/585/0637
A10: Alte Leipziger Leben | B10: vertrieb@alte-leipziger.de
A11: Alte Leipziger Sach | B11: vertrieb@alte-leipziger.de
A12: ARAG | B12: bu-makler@arag.de
A13: Barmenia Versicherung | B13: md-leipzig@barmenia.de
A14: Die Bayerische | B14: provisionsreklamation@diebayerische.de
A15: Ergo | B15: maklerauftraege-b@ergo.de | M15: 886986 | O15: (H) 887884 (V) 886986
A16: Generali Sach | B16: gen-maklerauftrag@generali.de | C16: 122700 | G16: 103677 | M16: 122700 | N16: 293181 | O16: 122700 | P16: 122700
A17: Generali Kfz | C17: 122700 | G17: 103679
A18: Generali Leben
A19: Gothaer Leben | B19: lv_service@gothaer.de | C19: 691-2336
A20: Gothaer Kranken | B20: kv_service@gothaer.de
A21: Gothaer Sach | B21: gkc_mm@gothaer.de | C21: 28446
A22: Hanse-Merkur | B22: Heiko.Domigalle@hansemerkur.de | M22: 221/1200468 | O22: 221/1200468 | P22: 221/1200468
A23: Hallesche Kranken | B23: VTW-ZK-ZB@alte-leipziger.de
A24: HDI Leben | B24: leben.service@hdi.de | M24: 203-44780 | N24: 203166 | O24: 021449
A25: HDI Sach | B25: HK.Vertrag@hdi.de
A26: Invers | B26: bestandsuebertragung@invers-gruppe.de | C26: 7993201 | G26: 7993201-013 | M26: 7993201-xx
A27: Inter | B27: maklerservice@inter.de | E27: 568063
A28: Kravag | B28: G_Vertriebsverwaltung_Makler@ruv.de | N28: 770/771072
A29: LV 1871 | B29: florian.steinhilber@lv1871.de | O29: 23 288830
A30: Nürnberger Leben | B30: michael.hoffmann@nuernberger.de | C30: 152053992 | O30: 152/05/3992
A31: Nürnberger Sach | B31: Ronald.Schleicher@nuernberger.de | C31: 152053992 | M31: 152/05/3992 | P31: 152/05/3992
A32: Mannheimer | B32: mdleipzig@mannheimer.de | E32: 522/89456 | M32: 522/60720 | P32: 522/66982
A33: Maxpool
A34: Rhion Versicherung | B34: zva@rhion.de
A35: Signal | B35: maklerauftrag@signal-iduna.de | M35: 1370/02419
A36: Volkswohlbund | B36: kc-ost@volkswohl-bund.de | M36: 184/204 | O36: 184/204
A37: Württembergische | B37: mandatsbearbeitung@wuerttembergische.de | M37: 6810-7150-4 | N37: 6810-7151-2 | O37: 6850-5223-7
A39: ansonsten über Maklerbetreuer einreichen

Sheet Post
A1: Gesellschaft | B1: Art der Zustellung | C1: Zugang
A2: Advocard | C2: Briefpost
A3: Allianz | B3: AMS/Concenter | C3: Briefpost | E3: Doppelerfassung
A4: Alte Leipziger | B4: AMS/Concenter
A5: ASC | B5: AMS/Concenter
A6: AXA | B6: AMS/Concenter | C6: Briefpost | D6: Maklerportal | E6: nur csv
A7: Baden-Badener | B7: AMS/Concenter
A8: Barmenia | B8: Easy Login
A9: Basler | C9: Briefpost
A10: Canada Life | B10: Easy Login
A11: Concordia
A12: Condor | B12: über R+V
A13: Continentale | B13: AMS/Concenter | C13: Transferservice | D13: Easy-Login | E13: gdv
A14: die Bayerische | C14: Briefpost
A15: Direct Line | B15: E-Mail | C15: Portal
A16: DBV | B16: AMS/Concenter | C16: Briefpost
A17: Easy Login
A18: Generali | C18: Briefpost
A19: Gothaer | B19: AMS/Concenter
A20: Haftpflichtkasse | B20: AMS/Concenter
A21: Hanse Merkur | B21: E-Mail
A22: HDI | B22: AMS/Concenter | C22: Transferservice | D22: Easy-Login | E22: Doppelerfassung
A23: Helvetia | B23: E-Mail
A24: Ideal | B24: E-Mail
A25: Inter | B25: Extranet
A26: Interlloyd | B26: Extranet
A27: Interrisk | C27: Briefpost
A28: Invers | B28: Extranet
A29: Janitos | B29: Portal | C29: keine Briefpost
A30: KRAVAG | B30: AMS/Concenter | C30: Briefpost
A31: KS-Auxilia
A32: LV1871 | B32: AMS/Concenter | C32: Transferservice | D32: Easy-Login
A33: Nürnberger | B33: AMS/Concenter | E33: PDF; GDV
A34: R+V Versicherung | B34: AMS/Concenter | C34: Briefpost
A35: Rhion | B35: AMS/Concenter | E35: PDF
A36: Stuttgarter | B36: AMS/Concenter
A37: TGIC
A38: VEMA | B38: AMS/Concenter
A39: VHV
A40: Volkswohlbund | B40: AMS/Concenter | C40: Transferservice | D40: Easy-Login | E40: PDF
...

Sheet Einzel
A1: =+'ex BH PW'!H1 -> Gesellschaft / Partner | B1: =+'ex BH PW'!J1 -> BeraterHaus | C1: =+'ex BH PW'!I1 -> VEMA | D1: =+'ex BH PW'!K1 -> ASC | E1: =+'ex BH PW'!L1 -> Invers | F1: =+'ex BH PW'!N1 -> maxpool | G1: =+'ex BH PW'!P1 -> Petri | H1: =+'ex BH PW'!Q1 -> Tippmann | I1: =+'ex BH PW'!R1 -> Röder | J1: =+'ex BH PW'!S1 -> Hesselbarth | K1: =+'ex BH PW'!T1 -> Furch | L1: =+'ex BH PW'!U1 -> Hartkopf | M1: =+'ex BH PW'!V1 -> Hildebrandt | N1: =+'ex BH PW'!W1 -> Hollatz | ... Z1: =+'ex BH PW'!AI1 -> Reif
A2: =+'ex BH PW'!H2 -> AAB Augsburger Aktienbank (Invers) | B2: =+'ex BH PW'!J2 -> 0 | C2: =+'ex BH PW'!I2 -> 0 | D2: =+'ex BH PW'!K2 -> 0 | E2: =+'ex BH PW'!L2 -> 0 | F2: =+'ex BH PW'!M2 -> 0 | G2: =+'ex BH PW'!N2 -> 0 | H2: =+'ex BH PW'!P2 -> 0 | I2: =+'ex BH PW'!Q2 -> 0 | J2: =+'ex BH PW'!R2 -> 0 | K2: =+'ex BH PW'!S2 -> 0 | L2: =+'ex BH PW'!T2 -> 0 | M2: =+'ex BH PW'!U2 -> 0 | N2: =+'ex BH PW'!V2 -> 0 | O2: =+'ex BH PW'!W2 -> 0 | ... Z2: =+'ex BH PW'!AH2 -> 0
A3: =+'ex BH PW'!H4 -> abc-teleconsult | B3: =+'ex BH PW'!J4 -> 0 | C3: =+'ex BH PW'!I4 -> 0 | D3: =+'ex BH PW'!K4 -> 0 | E3: =+'ex BH PW'!L4 -> 0 | F3: =+'ex BH PW'!M4 -> 0 | G3: =+'ex BH PW'!N4 -> 0 | H3: =+'ex BH PW'!P4 -> 0 | I3: =+'ex BH PW'!Q4 -> 0 | J3: =+'ex BH PW'!R4 -> 0 | K3: =+'ex BH PW'!S4 -> 0 | L3: =+'ex BH PW'!T4 -> 0 | M3: =+'ex BH PW'!U4 -> 0 | N3: =+'ex BH PW'!V4 -> 0 | O3: =+'ex BH PW'!W4 -> 0 | ... Z3: =+'ex BH PW'!AH4 -> 0
A4: =+'ex BH PW'!H5 -> ACE European Group Limited Direktion für Deutschland | B4: =+'ex BH PW'!J5 | C4: =+'ex BH PW'!I5 -> 2202_VEMA | D4: =+'ex BH PW'!K5 -> 0 | E4: =+'ex BH PW'!L5 -> 0 | F4: =+'ex BH PW'!M5 -> 0 | G4: =+'ex BH PW'!N5 -> 0 | H4: =+'ex BH PW'!P5 -> 0 | I4: =+'ex BH PW'!Q5 -> 0 | J4: =+'ex BH PW'!R5 -> 0 | K4: =+'ex BH PW'!S5 -> 0 | L4: =+'ex BH PW'!T5 -> 0 | M4: =+'ex BH PW'!U5 -> 0 | N4: =+'ex BH PW'!V5 -> 0 | O4: =+'ex BH PW'!W5 -> 0 | ... Z4: =+'ex BH PW'!AH5 -> 0
A5: =+'ex BH PW'!H6 -> Adcuri | B5: =+'ex BH PW'!J6 -> 950086739 | C5: =+'ex BH PW'!I6 -> 950212022 | D5: =+'ex BH PW'!K6 -> 0 | E5: =+'ex BH PW'!L6 -> 0 | F5: =+'ex BH PW'!M6 -> 0 | G5: =+'ex BH PW'!N6 -> 0 | H5: =+'ex BH PW'!P6 -> 0 | I5: =+'ex BH PW'!Q6 -> 0 | J5: =+'ex BH PW'!R6 -> 0 | K5: =+'ex BH PW'!S6 -> 0 | L5: =+'ex BH PW'!T6 -> 0 | M5: =+'ex BH PW'!U6 -> 0 | N5: =+'ex BH PW'!V6 -> 0 | O5: =+'ex BH PW'!W6 -> 0 | ... Z5: =+'ex BH PW'!AH6 -> 0
A6: =+'ex BH PW'!H8 -> Adcuri (VEMA) | B6: =+'ex BH PW'!J8 -> 950205963 alt | C6: =+'ex BH PW'!I8 -> 950212022 | D6: =+'ex BH PW'!K8 -> 0 | E6: =+'ex BH PW'!L8 -> 0 | F6: =+'ex BH PW'!M8 -> 0 | G6: =+'ex BH PW'!N8 -> 0 | H6: =+'ex BH PW'!P8 -> 0 | I6: =+'ex BH PW'!Q8 -> 0 | J6: =+'ex BH PW'!R8 -> 0 | K6: =+'ex BH PW'!S8 -> 0 | L6: =+'ex BH PW'!T8 -> 0 | M6: =+'ex BH PW'!U8 -> 0 | N6: =+'ex BH PW'!V8 -> 0 | O6: =+'ex BH PW'!W8 -> 0 | ... Z6: =+'ex BH PW'!AH8 -> 0
A7: =+'ex BH PW'!H9 -> Advigon (ex CSS 80002841) | B7: =+'ex BH PW'!J9 -> 3780145 | C7: =+'ex BH PW'!I9 -> 3780145 | D7: =+'ex BH PW'!K9 -> 0 | E7: =+'ex BH PW'!L9 -> 0 | F7: =+'ex BH PW'!M9 -> 0 | G7: =+'ex BH PW'!N9 -> 0 | H7: =+'ex BH PW'!P9 -> 0 | I7: =+'ex BH PW'!Q9 -> 0 | J7: =+'ex BH PW'!R9 -> 0 | K7: =+'ex BH PW'!S9 -> 0 | L7: =+'ex BH PW'!T9 -> 0 | M7: =+'ex BH PW'!U9 -> 0 | N7: =+'ex BH PW'!V9 -> 0 | O7: =+'ex BH PW'!W9 -> 0 | ... Z7: =+'ex BH PW'!AH9 -> 0
A8: =+'ex BH PW'!H10 -> AdvoCard (Dialog) | B8: =+'ex BH PW'!J10 -> 70/5523/00122700 | C8: =+'ex BH PW'!I10 -> 106151 | D8: =+'ex BH PW'!K10 -> 0 | E8: =+'ex BH PW'!L10 -> 0 | F8: =+'ex BH PW'!M10 -> 0 | G8: =+'ex BH PW'!N10 -> 0 | H8: =+'ex BH PW'!P10 -> 590/5509 | I8: =+'ex BH PW'!Q10 -> 0 | J8: =+'ex BH PW'!R10 -> 0 | K8: =+'ex BH PW'!S10 -> 0 | L8: =+'ex BH PW'!T10 -> 0 | M8: =+'ex BH PW'!U10 -> 0 | N8: =+'ex BH PW'!V10 -> 0 | O8: =+'ex BH PW'!W10 -> 0 | ... Z8: =+'ex BH PW'!AH10 -> 0
A9: =+[1]passwörter_agenturen!#REF! -> #REF! | B9: =+[1]passwörter_agenturen!#REF! -> #REF! | C9: =+[1]passwörter_agenturen!#REF! -> #REF! | D9: =+[1]passwörter_agenturen!#REF! -> #REF! | E9: =+[1]passwörter_agenturen!#REF! -> #REF! | F9: =+[1]passwörter_agenturen!#REF! -> #REF! | G9: =+[1]passwörter_agenturen!#REF! -> #REF! | H9: =+[1]passwörter_agenturen!#REF! -> #REF! | ... Z9: =+[1]passwörter_agenturen!#REF! -> #REF!
A10: =+'ex BH PW'!H12 -> AIG Europe Limited (Marke WüBa) | B10: =+'ex BH PW'!J12 -> 16603000 | C10: =+'ex BH PW'!I12 -> 16603000 | D10: =+'ex BH PW'!K12 -> 0 | E10: =+'ex BH PW'!L12 -> 0 | F10: =+'ex BH PW'!M12 -> 0 | G10: =+'ex BH PW'!N12 -> 0 | H10: =+'ex BH PW'!P12 -> 0 | I10: =+'ex BH PW'!Q12 -> 0 | J10: =+'ex BH PW'!R12 -> 0 | K10: =+'ex BH PW'!S12 -> 0 | L10: =+'ex BH PW'!T12 -> 0 | M10: =+'ex BH PW'!U12 -> 0 | N10: =+'ex BH PW'!V12 -> 0 | O10: =+'ex BH PW'!W12 -> 0 | ... Z10: =+'ex BH PW'!AH12 -> 0
A11: =+'ex BH PW'!H13 -> Allianz Leben | B11: =+'ex BH PW'!J13 -> 50/110/2650 | C11: =+'ex BH PW'!I13 -> 50/110/2650 | D11: =+'ex BH PW'!K13 -> 0 | E11: =+'ex BH PW'!L13 -> 0 | F11: =+'ex BH PW'!M13 -> 0 | G11: =+'ex BH PW'!N13 -> 0 | H11: =+'ex BH PW'!P13 -> 0 | I11: =+'ex BH PW'!Q13 -> 0 | J11: =+'ex BH PW'!R13 -> 0 | K11: =+'ex BH PW'!S13 -> 0 | L11: =+'ex BH PW'!T13 -> 0 | M11: =+'ex BH PW'!U13 -> 0 | N11: =+'ex BH PW'!V13 -> 0 | O11: =+'ex BH PW'!W13 -> 0 | ... Z11: =+'ex BH PW'!AH13 -> 0
A12: =+'ex BH PW'!H14 -> Allianz Kranken | B12: =+'ex BH PW'!J14 -> 70/585/0637 | C12: =+'ex BH PW'!I14 -> 705850637 | D12: =+'ex BH PW'!K14 -> 0 | E12: =+'ex BH PW'!L14 -> 0 | F12: =+'ex BH PW'!M14 -> 0 | G12: =+'ex BH PW'!N14 -> 0 | H12: =+'ex BH PW'!P14 -> 0 | I12: =+'ex BH PW'!Q14 -> 0 | J12: =+'ex BH PW'!R14 -> 0 | K12: =+'ex BH PW'!S14 -> 0 | L12: =+'ex BH PW'!T14 -> 0 | M12: =+'ex BH PW'!U14 -> 0 | N12: =+'ex BH PW'!V14 -> 0 | O12: =+'ex BH PW'!W14 -> 0 | ... Z12: =+'ex BH PW'!AH14 -> 0
A13: =+'ex BH PW'!H16 -> Alte Leipziger Bauspar AG | B13: =+'ex BH PW'!J16 -> 5124 | C13: =+'ex BH PW'!I16 -> 0 | D13: =+'ex BH PW'!K16 -> 0 | E13: =+'ex BH PW'!L16 -> 0 | F13: =+'ex BH PW'!M16 -> 0 | G13: =+'ex BH PW'!N16 -> 0 | H13: =+'ex BH PW'!P16 -> 0 | I13: =+'ex BH PW'!Q16 -> 0 | J13: =+'ex BH PW'!R16 -> 0 | K13: =+'ex BH PW'!S16 -> 0 | L13: =+'ex BH PW'!T16 -> 0 | M13: =+'ex BH PW'!U16 -> 0 | N13: =+'ex BH PW'!V16 -> 0 | O13: =+'ex BH PW'!W16 -> 0 | ... Z13: =+'ex BH PW'!AH16 -> 0
A14: =+'ex BH PW'!H18 -> Amex | B14: =+'ex BH PW'!J18 -> 55956 | C14: =+'ex BH PW'!I18 -> 0 | D14: =+'ex BH PW'!K18 -> 0 | E14: =+'ex BH PW'!L18 -> 0 | F14: =+'ex BH PW'!M18 -> 0 | G14: =+'ex BH PW'!N18 -> 0 | H14: =+'ex BH PW'!P18 -> 0 | I14: =+'ex BH PW'!Q18 -> 0 | J14: =+'ex BH PW'!R18 -> 0 | K14: =+'ex BH PW'!S18 -> 0 | L14: =+'ex BH PW'!T18 -> 0 | M14: =+'ex BH PW'!U18 -> 0 | N14: =+'ex BH PW'!V18 -> 0 | O14: =+'ex BH PW'!W18 -> 0 | ... Z14: =+'ex BH PW'!AH18 -> 0
A15: =+'ex BH PW'!H19 -> Ammerländer | B15: =+'ex BH PW'!J19 -> 24600 | C15: =+'ex BH PW'!I19 -> 24600 | D15: =+'ex BH PW'!K19 -> 0 | E15: =+'ex BH PW'!L19 -> 0 | F15: =+'ex BH PW'!M19 -> 0 | G15: =+'ex BH PW'!N19 -> 0 | H15: =+'ex BH PW'!P19 -> 0 | I15: =+'ex BH PW'!Q19 -> 0 | J15: =+'ex BH PW'!R19 -> 0 | K15: =+'ex BH PW'!S19 -> 0 | L15: =+'ex BH PW'!T19 -> 0 | M15: =+'ex BH PW'!U19 -> 0 | N15: =+'ex BH PW'!V19 -> 0 | O15: =+'ex BH PW'!W19 -> 0 | ... Z15: =+'ex BH PW'!AH19 -> 0
A16: =+'ex BH PW'!H20 -> Ammerländer | B16: =+'ex BH PW'!J20 -> 0 | C16: =+'ex BH PW'!I20 -> 24600 | D16: =+'ex BH PW'!K20 -> 0 | E16: =+'ex BH PW'!L20 -> 0 | F16: =+'ex BH PW'!M20 -> 0 | G16: =+'ex BH PW'!N20 -> 0 | H16: =+'ex BH PW'!P20 -> 0 | I16: =+'ex BH PW'!Q20 -> 0 | J16: =+'ex BH PW'!R20 -> 0 | K16: =+'ex BH PW'!S20 -> 0 | L16: =+'ex BH PW'!T20 -> 0 | M16: =+'ex BH PW'!U20 -> 0 | N16: =+'ex BH PW'!V20 -> 0 | O16: =+'ex BH PW'!W20 -> 0 | ... Z16: =+'ex BH PW'!AH20 -> 0
A17: =+'ex BH PW'!H22 -> Apella | B17: =+'ex BH PW'!J22 -> 05065 | C17: =+'ex BH PW'!I22 -> 0 | D17: =+'ex BH PW'!K22 -> 0 | E17: =+'ex BH PW'!L22 -> 0 | F17: =+'ex BH PW'!M22 -> 0 | G17: =+'ex BH PW'!N22 -> 0 | H17: =+'ex BH PW'!P22 -> 0 | I17: =+'ex BH PW'!Q22 -> 0 | J17: =+'ex BH PW'!R22 -> 0 | K17: =+'ex BH PW'!S22 -> 0 | L17: =+'ex BH PW'!T22 -> 0 | M17: =+'ex BH PW'!U22 -> 0 | N17: =+'ex BH PW'!V22 -> 0 | O17: =+'ex BH PW'!W22 -> 0 | ... Z17: =+'ex BH PW'!AH22 -> 0
A18: =+'ex BH PW'!H23 -> Apella | B18: =+'ex BH PW'!J23 -> 0 | C18: =+'ex BH PW'!I23 -> 0 | D18: =+'ex BH PW'!K23 -> 0 | E18: =+'ex BH PW'!L23 -> 0 | F18: =+'ex BH PW'!M23 -> 0 | G18: =+'ex BH PW'!N23 -> 0 | H18: =+'ex BH PW'!P23 -> 0 | I18: =+'ex BH PW'!Q23 -> 0 | J18: =+'ex BH PW'!R23 -> 0 | K18: =+'ex BH PW'!S23 -> 0 | L18: =+'ex BH PW'!T23 -> 0 | M18: =+'ex BH PW'!U23 -> 0 | N18: =+'ex BH PW'!V23 -> 0 | O18: =+'ex BH PW'!W23 -> 0 | ... Z18: =+'ex BH PW'!AH23 -> 0
A19: =+'ex BH PW'!H24 -> ARAG Krankenversicherungen | B19: =+'ex BH PW'!J24 -> 643/060344 | C19: =+'ex BH PW'!I24 -> 60344 | D19: =+'ex BH PW'!K24 -> 0 | E19: =+'ex BH PW'!L24 -> 0 | F19: =+'ex BH PW'!M24 -> 0 | G19: =+'ex BH PW'!N24 -> 0 | H19: =+'ex BH PW'!P24 -> 0 | I19: =+'ex BH PW'!Q24 -> 0 | J19: =+'ex BH PW'!R24 -> 0 | K19: =+'ex BH PW'!S24 -> 0 | L19: =+'ex BH PW'!T24 -> 0 | M19: =+'ex BH PW'!U24 -> 0 | N19: =+'ex BH PW'!V24 -> 0 | O19: =+'ex BH PW'!W24 -> 0 | ... Z19: =+'ex BH PW'!AH24 -> 0
A20: =+'ex BH PW'!H25 -> ARAG Rechtsschutzversicherung | B20: =+'ex BH PW'!J25 -> 643/AA2481-3 | C20: =+'ex BH PW'!I25 -> AA2481-3 | D20: =+'ex BH PW'!K25 -> 0 | E20: =+'ex BH PW'!L25 -> 7975101 | F20: =+'ex BH PW'!M25 -> 0 | G20: =+'ex BH PW'!N25 -> 0 | H20: =+'ex BH PW'!P25 -> 0 | I20: =+'ex BH PW'!Q25 -> 0 | J20: =+'ex BH PW'!R25 -> 0 | K20: =+'ex BH PW'!S25 -> 0 | L20: =+'ex BH PW'!T25 -> 0 | M20: =+'ex BH PW'!U25 -> 0 | N20: =+'ex BH PW'!V25 -> 0 | O20: =+'ex BH PW'!W25 -> 0 | ... Z20: =+'ex BH PW'!AH25 -> 0
A21: =+'ex BH PW'!H26 -> ARAG Versicherungen | B21: =+'ex BH PW'!J26 -> 643/AA2481-3 | C21: =+'ex BH PW'!I26 -> AA2481-3 | D21: =+'ex BH PW'!K26 -> 0 | E21: =+'ex BH PW'!L26 -> 0 | F21: =+'ex BH PW'!M26 -> 0 | G21: =+'ex BH PW'!N26 -> 0 | H21: =+'ex BH PW'!P26 -> 0 | I21: =+'ex BH PW'!Q26 -> 0 | J21: =+'ex BH PW'!R26 -> 0 | K21: =+'ex BH PW'!S26 -> 0 | L21: =+'ex BH PW'!T26 -> 0 | M21: =+'ex BH PW'!U26 -> 0 | N21: =+'ex BH PW'!V26 -> 0 | O21: =+'ex BH PW'!W26 -> 0 | ... Z21: =+'ex BH PW'!AH26 -> 0
A22: =+'ex BH PW'!H27 -> ASC | B22: =+'ex BH PW'!J27 -> 89299 | C22: =+'ex BH PW'!I27 -> 0 | D22: =+'ex BH PW'!K27 -> 0 | E22: =+'ex BH PW'!L27 -> 0 | F22: =+'ex BH PW'!M27 -> 0 | G22: =+'ex BH PW'!N27 -> 0 | H22: =+'ex BH PW'!P27 -> 0 | I22: =+'ex BH PW'!Q27 -> 0 | J22: =+'ex BH PW'!R27 -> 0 | K22: =+'ex BH PW'!S27 -> 0 | L22: =+'ex BH PW'!T27 -> 0 | M22: =+'ex BH PW'!U27 -> 0 | N22: =+'ex BH PW'!V27 -> 0 | O22: =+'ex BH PW'!W27 -> 0 | ... Z22: =+'ex BH PW'!AH27 -> 0
A23: =+'ex BH PW'!H28 -> Athora (alt Athene ;Delta Lloyd) | B23: =+'ex BH PW'!J28 -> 4187038 | C23: =+'ex BH PW'!I28 -> 0 | D23: =+'ex BH PW'!K28 -> 0 | E23: =+'ex BH PW'!L28 -> 0 | F23: =+'ex BH PW'!M28 -> 0 | G23: =+'ex BH PW'!N28 -> 0 | H23: =+'ex BH PW'!P28 -> 0 | I23: =+'ex BH PW'!Q28 -> 0 | J23: =+'ex BH PW'!R28 -> 0 | K23: =+'ex BH PW'!S28 -> 0 | L23: =+'ex BH PW'!T28 -> 0 | M23: =+'ex BH PW'!U28 -> 0 | N23: =+'ex BH PW'!V28 -> 0 | O23: =+'ex BH PW'!W28 -> 0 | ... Z23: =+'ex BH PW'!AH28 -> 0
A24: =+'ex BH PW'!H29 -> AUXILIA Rechtsschutz-Versicherungs AG | B24: =+'ex BH PW'!J29 -> 107175 | C24: =+'ex BH PW'!I29 -> 107175 | D24: =+'ex BH PW'!K29 -> 0 | E24: =+'ex BH PW'!L29 -> 108980 | F24: =+'ex BH PW'!M29 -> 0 | G24: =+'ex BH PW'!N29 -> 0 | H24: =+'ex BH PW'!P29 -> 0 | I24: =+'ex BH PW'!Q29 -> 0 | J24: =+'ex BH PW'!R29 -> 0 | K24: =+'ex BH PW'!S29 -> 0 | L24: =+'ex BH PW'!T29 -> 112366 | M24: =+'ex BH PW'!U29 -> 0 | N24: =+'ex BH PW'!V29 -> 0 | O24: =+'ex BH PW'!W29 -> 0 | ... Z24: =+'ex BH PW'!AH29 -> 0
A25: =+'ex BH PW'!H30 -> AXA (Innendienst) Kfz | B25: =+'ex BH PW'!J30 -> 0 | C25: =+'ex BH PW'!I30 -> 0 | D25: =+'ex BH PW'!K30 -> 0 | E25: =+'ex BH PW'!L30 -> 0 | F25: =+'ex BH PW'!M30 -> 0 | G25: =+'ex BH PW'!N30 -> 0 | H25: =+'ex BH PW'!P30 -> 10/48/00/1783 | I25: =+'ex BH PW'!Q30 -> 10/48/00/1778 | J25: =+'ex BH PW'!R30 -> 0 | K25: =+'ex BH PW'!S30 -> 0 | L25: =+'ex BH PW'!T30 -> 0 | M25: =+'ex BH PW'!U30 -> 0 | N25: =+'ex BH PW'!V30 -> 0 | O25: =+'ex BH PW'!W30 -> 0 | ... Z25: =+'ex BH PW'!AH30 -> 0
A26: =+'ex BH PW'!H31 -> AXA Leben | B26: =+'ex BH PW'!J31 -> 10/35/00/6249 | C26: =+'ex BH PW'!I31 -> 1035006249 | D26: =+'ex BH PW'!K31 -> 0 | E26: =+'ex BH PW'!L31 -> 0 | F26: =+'ex BH PW'!M31 -> 0 | G26: =+'ex BH PW'!N31 -> 0 | H26: =+'ex BH PW'!P31 -> 0 | I26: =+'ex BH PW'!Q31 -> 0 | J26: =+'ex BH PW'!R31 -> 0 | K26: =+'ex BH PW'!S31 -> 0 | L26: =+'ex BH PW'!T31 -> 0 | M26: =+'ex BH PW'!U31 -> 0 | N26: =+'ex BH PW'!V31 -> 0 | O26: =+'ex BH PW'!W31 -> 0 | ... Z26: =+'ex BH PW'!AH31 -> 0
A27: =+'ex BH PW'!H32 -> AXA Leben (alt DBV-Leben) | B27: =+'ex BH PW'!J32 -> 10/36/00/2754 | C27: =+'ex BH PW'!I32 -> 0 | D27: =+'ex BH PW'!K32 -> 0 | E27: =+'ex BH PW'!L32 -> 0 | F27: =+'ex BH PW'!M32 -> 0 | G27: =+'ex BH PW'!N32 -> 0 | H27: =+'ex BH PW'!P32 -> 0 | I27: =+'ex BH PW'!Q32 -> 0 | J27: =+'ex BH PW'!R32 -> 0 | K27: =+'ex BH PW'!S32 -> 0 | L27: =+'ex BH PW'!T32 -> 0 | M27: =+'ex BH PW'!U32 -> 0 | N27: =+'ex BH PW'!V32 -> 0 | O27: =+'ex BH PW'!W32 -> 0 | ... Z27: =+'ex BH PW'!AH32 -> 0
A28: =+'ex BH PW'!H33 -> AXA Sach | B28: =+'ex BH PW'!J33 -> 10/48/00/0805 | C28: =+'ex BH PW'!I33 -> 1048000805, 1048001741, 1048001767, 1048001772, | D28: =+'ex BH PW'!K33 -> 0 | E28: =+'ex BH PW'!L33 -> 0 | F28: =+'ex BH PW'!M33 -> 0 | G28: =+'ex BH PW'!N33 -> 0 | H28: =+'ex BH PW'!P33 -> 10/48/00/1767 | I28: =+'ex BH PW'!Q33 -> 10/48/00/1741 | J28: =+'ex BH PW'!R33 -> 10/48/00/1772 | K28: =+'ex BH PW'!S33 -> 0 | L28: =+'ex BH PW'!T33 -> 0 | M28: =+'ex BH PW'!U33 -> 0 | N28: =+'ex BH PW'!V33 -> 10/48/00/1791 | O28: =+'ex BH PW'!W33 -> 10/48/00/1296 | ... Z28: =+'ex BH PW'!AH33 -> 0
A29: =+'ex BH PW'!H34 -> AXA Sach (Rahmenvertrag Kfz) | B29: =+'ex BH PW'!J34 -> 130040363 | C29: =+[1]passwörter_agenturen!#REF! -> #REF! | D29: =+'ex BH PW'!K34 -> 0 | E29: =+'ex BH PW'!L34 -> 0 | F29: =+'ex BH PW'!M34 -> 0 | G29: =+'ex BH PW'!N34 -> 0 | H29: =+'ex BH PW'!P34 -> 0 | I29: =+'ex BH PW'!Q34 -> 0 | J29: =+'ex BH PW'!R34 -> 0 | K29: =+'ex BH PW'!S34 -> 0 | L29: =+'ex BH PW'!T34 -> 0 | M29: =+'ex BH PW'!U34 -> 0 | N29: =+'ex BH PW'!V34 -> 0 | O29: =+'ex BH PW'!W34 -> 0 | ... Z29: =+'ex BH PW'!AH34 -> 0
A30: =+'ex BH PW'!H35 -> AXA Sach (Rahmenvertrag Sach) | B30: =+'ex BH PW'!J35 -> 003816 | C30: =+'ex BH PW'!I34 -> 0 | D30: =+'ex BH PW'!K35 -> 0 | E30: =+'ex BH PW'!L35 -> 0 | F30: =+'ex BH PW'!M35 -> 0 | G30: =+'ex BH PW'!N35 -> 0 | H30: =+'ex BH PW'!P35 -> 0 | I30: =+'ex BH PW'!Q35 -> 0 | J30: =+'ex BH PW'!R35 -> 0 | K30: =+'ex BH PW'!S35 -> 0 | L30: =+'ex BH PW'!T35 -> 0 | M30: =+'ex BH PW'!U35 -> 0 | N30: =+'ex BH PW'!V35 -> 0 | O30: =+'ex BH PW'!W35 -> 0 | ... Z30: =+'ex BH PW'!AH35 -> 0
A31: =+'ex BH PW'!H37 -> Zurich Sach / fbs (ex Baden-Badener) | B31: =+'ex BH PW'!J37 -> 782644 | C31: =+'ex BH PW'!I37 -> 0 | D31: =+'ex BH PW'!K37 -> 0 | E31: =+'ex BH PW'!L37 -> 76993201 | F31: =+'ex BH PW'!M37 -> 0 | G31: =+'ex BH PW'!N37 -> 0 | H31: =+'ex BH PW'!P37 -> 0 | I31: =+'ex BH PW'!Q37 -> 0 | J31: =+'ex BH PW'!R37 -> 0 | K31: =+'ex BH PW'!S37 -> 0 | L31: =+'ex BH PW'!T37 -> 0 | M31: =+'ex BH PW'!U37 -> 0 | N31: =+'ex BH PW'!V37 -> 0 | O31: =+'ex BH PW'!W37 -> 0 | ... Z31: =+'ex BH PW'!AH37 -> 0
A32: =+'ex BH PW'!H41 -> Baloise Lebensversicherung AG | B32: =+'ex BH PW'!J41 -> 871/0929 | C32: =+'ex BH PW'!I41 -> 871/0929 | D32: =+'ex BH PW'!K41 -> 0 | E32: =+'ex BH PW'!L41 -> 0 | F32: =+'ex BH PW'!M41 -> 0 | G32: =+'ex BH PW'!N41 -> 0 | H32: =+'ex BH PW'!P41 -> 0 | I32: =+'ex BH PW'!Q41 -> 0 | J32: =+'ex BH PW'!R41 -> 0 | K32: =+'ex BH PW'!S41 -> 0 | L32: =+'ex BH PW'!T41 -> 0 | M32: =+'ex BH PW'!U41 -> 0 | N32: =+'ex BH PW'!V41 -> 0 | O32: =+'ex BH PW'!W41 -> 0 | ... Z32: =+'ex BH PW'!AH41 -> 0
A33: =+'ex BH PW'!H42 -> BSG Baloise Service GmbH | B33: =+'ex BH PW'!J42 -> 0 | C33: =+'ex BH PW'!I42 -> 2202-00 | D33: =+'ex BH PW'!K42 -> 0 | E33: =+'ex BH PW'!L42 -> 0 | F33: =+'ex BH PW'!M42 -> 0 | G33: =+'ex BH PW'!N42 -> 0 | H33: =+'ex BH PW'!P42 -> 0 | I33: =+'ex BH PW'!Q42 -> 0 | J33: =+'ex BH PW'!R42 -> 0 | K33: =+'ex BH PW'!S42 -> 0 | L33: =+'ex BH PW'!T42 -> 0 | M33: =+'ex BH PW'!U42 -> 0 | N33: =+'ex BH PW'!V42 -> 0 | O33: =+'ex BH PW'!W42 -> 0 | ... Z33: =+'ex BH PW'!AH42 -> 0
A34: =+'ex BH PW'!H44 -> Bayerische Hausbesitzer Versicherung | B34: =+'ex BH PW'!J44 -> 6255 | C34: =+'ex BH PW'!I44 -> 6255 | D34: =+'ex BH PW'!K44 -> 0 | E34: =+'ex BH PW'!L44 -> 0 | F34: =+'ex BH PW'!M44 -> 0 | G34: =+'ex BH PW'!N44 -> 0 | H34: =+'ex BH PW'!P44 -> 0 | I34: =+'ex BH PW'!Q44 -> 0 | J34: =+'ex BH PW'!R44 -> 0 | K34: =+'ex BH PW'!S44 -> 0 | L34: =+'ex BH PW'!T44 -> 0 | M34: =+'ex BH PW'!U44 -> 0 | N34: =+'ex BH PW'!V44 -> 0 | O34: =+'ex BH PW'!W44 -> 0 | ... Z34: =+'ex BH PW'!AH44 -> 0
A35: =+[1]passwörter_agenturen!#REF! -> #REF! | B35: =+[1]passwörter_agenturen!#REF! -> #REF! | C35: =+[1]passwörter_agenturen!#REF! -> #REF! | D35: =+[1]passwörter_agenturen!#REF! -> #REF! | E35: =+[1]passwörter_agenturen!#REF! -> #REF! | F35: =+[1]passwörter_agenturen!#REF! -> #REF! | G35: =+[1]passwörter_agenturen!#REF! -> #REF! | H35: =+[1]passwörter_agenturen!#REF! -> #REF! | ... Z35: =+[1]passwörter_agenturen!#REF! -> #REF!
A36: =+'ex BH PW'!H46 -> BHW (Invers) | B36: =+'ex BH PW'!J46 -> 0 | C36: =+'ex BH PW'!I46 -> 0 | D36: =+'ex BH PW'!K46 -> 0 | E36: =+'ex BH PW'!L46 -> 02431917357 | F36: =+'ex BH PW'!M46 -> 0 | G36: =+'ex BH PW'!N46 -> 0 | H36: =+'ex BH PW'!P46 -> 0 | I36: =+'ex BH PW'!Q46 -> 0 | J36: =+'ex BH PW'!R46 -> 0 | K36: =+'ex BH PW'!S46 -> 0 | L36: =+'ex BH PW'!T46 -> 0 | M36: =+'ex BH PW'!U46 -> 0 | N36: =+'ex BH PW'!V46 -> 0 | O36: =+'ex BH PW'!W46 -> 0 | ... Z36: =+'ex BH PW'!AH46 -> 0
A37: =+'ex BH PW'!H47 -> BKM Bausparkasse Mainz | B37: =+'ex BH PW'!J47 -> 568063 | C37: =+'ex BH PW'!I47 -> 0 | D37: =+'ex BH PW'!K47 -> 0 | E37: =+'ex BH PW'!L47 -> 0 | F37: =+'ex BH PW'!M47 -> 0 | G37: =+'ex BH PW'!N47 -> 0 | H37: =+'ex BH PW'!P47 -> 0 | I37: =+'ex BH PW'!Q47 -> 0 | J37: =+'ex BH PW'!R47 -> 0 | K37: =+'ex BH PW'!S47 -> 0 | L37: =+'ex BH PW'!T47 -> 0 | M37: =+'ex BH PW'!U47 -> 0 | N37: =+'ex BH PW'!V47 -> 0 | O37: =+'ex BH PW'!W47 -> 0 | ... Z37: =+'ex BH PW'!AH47 -> 0
A38: =+'ex BH PW'!H48 -> Brandgilde Versicherung | B38: =+'ex BH PW'!J48 -> 14356 | C38: =+'ex BH PW'!I48 -> 0 | D38: =+'ex BH PW'!K48 -> 0 | E38: =+'ex BH PW'!L48 -> 0 | F38: =+'ex BH PW'!M48 -> 0 | G38: =+'ex BH PW'!N48 -> 0 | H38: =+'ex BH PW'!P48 -> 0 | I38: =+'ex BH PW'!Q48 -> 0 | J38: =+'ex BH PW'!R48 -> 0 | K38: =+'ex BH PW'!S48 -> 0 | L38: =+'ex BH PW'!T48 -> 0 | M38: =+'ex BH PW'!U48 -> 0 | N38: =+'ex BH PW'!V48 -> 0 | O38: =+'ex BH PW'!W48 -> 0 | ... Z38: =+'ex BH PW'!AH48 -> 0
A39: =+'ex BH PW'!H49 -> Canada Life | B39: =+'ex BH PW'!J49 -> A5G6 | C39: =+'ex BH PW'!I49 -> A5G6 | D39: =+'ex BH PW'!K49 -> 0 | E39: =+'ex BH PW'!L49 -> 0 | F39: =+'ex BH PW'!M49 -> 0 | G39: =+'ex BH PW'!N49 -> 0 | H39: =+'ex BH PW'!P49 -> 0 | I39: =+'ex BH PW'!Q49 -> 0 | J39: =+'ex BH PW'!R49 -> 0 | K39: =+'ex BH PW'!S49 -> 0 | L39: =+'ex BH PW'!T49 -> 0 | M39: =+'ex BH PW'!U49 -> 0 | N39: =+'ex BH PW'!V49 -> 0 | O39: =+'ex BH PW'!W49 -> 0 | ... Z39: =+'ex BH PW'!AH49 -> 0
A40: =+'ex BH PW'!H50 -> Care Concept | B40: =+'ex BH PW'!J50 -> 000 20 50000 | C40: =+'ex BH PW'!I50 -> 0 | D40: =+'ex BH PW'!K50 -> 0 | E40: =+'ex BH PW'!L50 -> 0 | F40: =+'ex BH PW'!M50 -> 0 | G40: =+'ex BH PW'!N50 -> 0 | H40: =+'ex BH PW'!P50 -> 0 | I40: =+'ex BH PW'!Q50 -> 0 | J40: =+'ex BH PW'!R50 -> 0 | K40: =+'ex BH PW'!S50 -> 0 | L40: =+'ex BH PW'!T50 -> 0 | M40: =+'ex BH PW'!U50 -> 0 | N40: =+'ex BH PW'!V50 -> 0 | O40: =+'ex BH PW'!W50 -> 0 | ... Z40: =+'ex BH PW'!AH50 -> 0
...

Sheet VEMA-Nr´n
A1: Vermittlernummern (alle Versicherer) Stand: 13.01.2017
A2: Versicherer | B2: VmNr | C2: Attribute
A3: Aachener Bausparkasse AG
A4: ACE European Group Limited Direktion für Deutschland | B4: 2202_VEMA | C4: keine Anbindung (VR)
A5: Adcuri | B5: 950212022
A6: Advigon Versicherung AG | B6: 3780145 | C6: Zuordnung bestätigt
A7: Aegon Niederlassung Deutschland der Aegon Ireland plc
A8: AIG Europe Limited (Marke WüBa) | B8: 16603-000 | C8: Zuordnung bestätigt
A9: ALLCURA Versicherungs-Aktiengesellschaft
A10: Allianz Versicherungen | B10: 0603123 | C10: Zuordnung bestätigt KV
A11: Allianz Versicherungen | B11: 2202_VEMA | C11: keine Anbindung (VR) Sach
A12: Allianz Versicherungen | B12: 501102650 | C12: Zuordnung bestätigt LV
A13: Allianz Versicherungen | B13: 702022262 | C13: Zuordnung bestätigt CZ beendet (VM) LV
A14: Allianz Versicherungen | B14: 705850637 | C14: Zuordnung bestätigt KV
A15: Allianz Esa cargo & logistics GmbH
A16: Allianz Global Assistance
A17: ALTE LEIPZIGER | B17: 580678001 | C17: nicht zugeordnet LV Sach
A18: ALTE LEIPZIGER | B18: 580678002 | C18: Verbundnummer
A19: Alte Oldenburger Krankenversicherung AG
A20: Amlin Insurance SE Direktion für Deutschland
A21: Ammerländer Versicherung VVaG | B21: 24600 | C21: Zuordnung bestätigt
A22: ANGLO Underwriting GmbH
A23: ARAG Versicherungen | B23: 2202_VEMA | C23: keine Anbindung (VR)
A24: Atradius Kreditversicherung
A25: AUXILIA Rechtsschutz-Versicherungs AG | B25: 107175 | C25: Zuordnung bestätigt
A26: AUXILIA Rechtsschutz-Versicherungs AG | B26: 112366 | C26: Zuordnung bestätigt CZ beendet (VM)
A27: AXA Versicherungen | B27: 1035006249 | C27: nicht zugeordnet LV
A28: AXA Versicherungen | B28: 1048000805 | C28: Zuordnung bestätigt Sach
A29: AXA Versicherungen | B29: 1048001741 | C29: nicht für Neugeschäft Sach
A30: AXA Versicherungen | B30: 1048001767 | C30: nicht für Neugeschäft Sach
A31: AXA Versicherungen | B31: 1048001772 | C31: nicht für Neugeschäft Sach
A32: AXA Versicherungen | B32: 1048001791 | C32: nicht für Neugeschäft Sach
A33: AXA Versicherungen | B33: 5707000805 | C33: nicht zugeordnet KV
A34: Baden-Badener Versicherung AG | B34: 782644 | C34: Zuordnung bestätigt
A35: Baloise Luxembourg
A36: Barmenia | B36: 0021/1650 | C36: nicht zugeordnet
A37: Basler Versicherungen | B37: 082225 | C37: Zuordnung bestätigt
A38: BavariaDirekt OVAG - Ostdeutsche Versicherung Aktiengesellschaft
A39: Bayerische Hausbesitzer-Versicherungs-Gesellschaft a.G. | B39: 6255 | C39: Zuordnung bestätigt
A40: Berliner Versicherung (BVAG)
...

Sheet Invers interne Nr´n
A1: Kurz. | B1: Anbieter | C1: Vermittler-Nr beim Anb.
A2: AAB | B2: Augsburger Aktienbank | C2: 9900133692
A3: ADC | B3: ADCURI | C3: 950094925
A4: ALTSA | B4: Alte Leipziger Sachversicherung | C4: 130656.466 Sach-Nr. 22-2409
A5: AUX | B5: Auxilia | C5: 108980
A6: AXASA | B6: AXA Sachversicherung | C6: 1036008206
A7: BAD | B7: Baden Badener | C7: 76993201
A8: BARKV | B8: Barmenia Versicherungen | C8: 0021/1695
A9: BASSA | B9: Basler Versicherungen | C9: 621-285
A10: BAYSA | B10: Bayerische Sachversicherung | C10: 090124
A11: CCOSA | B11: Concordia Versicherungsgesellschaft a.G. | C11: 55280-055
A12: DEURAG | B12: DEURAG Rechtsschutz AG | C12: 51089
... A39: ZURLV | B39: Zurich Deutscher Herold Lebensversicherung AG | C39: 222963

Sheet Frank Malzahn
A1: Adressenliste und Anmeldungen online
A3: Gesellschaft | B3: Adresse | C3: Telefon/Fax | D3: Verm.-Nr. | E3: Benutzer | F3: Passwort | G3: Internet-Adr.
A5: Apella AG | E5: 36809 | F5: 942876 | G5: www.apella.de
A9: Amex | E9: AX40464 | F9: 101045 | G9: www.amex-online.de
A12: Alte Leipziger AG | B12: Alte Leipziger Platz 1 | D12: 827053.001 Verb. VNR | E12: Malzahn.F | F12: 160568 | G12: www.al-vermittler.de
B13: 61440 Oberursel | D13: 23-9855 Frank Sach
E14: Malzahn.E | F14: 191108
A17: ARAG | B17: ARAG Platz 1 | C17: T 0211 9890 1616 | D17: 565/28214 | G17: www.arag.de
B18: 40472 Düsseldorf | C18: F 0211 963 2850
A20: AXA Versicherung AG | B20: Colonia Allee 10-20 | D20: 80/36/00/0462 Frank | E20: AXA35986 | F20: Katharina1 | G20: www.axa.de
B21: 51067 Köln | D21: 80/36/00/0633 Elke | F21: (auch für sichere Nachrichten)
A24: Baden Badener | D24: 77005410 | E24: 77005410 | F24: g2ihANUHC4 | G24: www.bb-maklerwelt.de.
A30: Bayerische | B30: Thomas-Dehler-Str-. 25 | C30: 0180 1228366 | D30: 6801 581213 Frank | E30: MAK581213-0001 | F30: FrankMal1 | G30: www.bbv.de
B31: 81737 München | D31: 6801 580370 Elke | E31: MAK580370-0001 | F31: FrankMal1
A34: Condor | B34: Admiralitätsstr. 67 | C34: T 040 36139 0 | D34: 78468 | E34: 78468 | F34: Katharina1 | G34: www.condor-versicherungsgruppe.de
B35: 20459 Hamburg | C35: F 040 36139-100 | E35: Anmeldung R+V
A38: Concordia | D38: 55197 | E38: 55197000 | F38: Cordial01 | G38: www.concordia.de
G40: Login allg.
A41: DEURAG | B41: Die Freiheit 14 | C41: T 0561/780061 | D41: 21003 | E41: 21003 | F41: FrankM | G41: www.rs.deurag.de
B42: 34117 Kassel | C42: F 0561 102973 | F42: Benutzer: malzahn | G42: www.deurag.de
F43: Passw.:KatharinaHe1 (31.5.16) | G43: für GDV-Download
E45: 9111984 | F45: bu3c#kH7 | G45: www.deutscherring-kranken-makler.de
A46: Deutscher Ring | B46: Ludwig-Erhard-Str. 22 | C46: T 040 3599-50 | D46: 5315/0001 | E46: Antr.-Bausparen(Begleitz.)
B47: 20459 Hamburg | C47: F 040 3599-5128 | E47: über Apella
D48: Sicherheitsfrage:
A49: easyLogin | C49: 0921 75758 555 | D49: Katharina Heußer | E49: vb027300880 | F49: FrankM | G49: www.easy-login.de
D50: Antw.: 13.06.1962
E51: Benutzername GDV | F51: FrankMal01 (08.01.2018)
A52: ERGO / Victoria | B52: Stresemannstr. 111 | C52: 030 88781- | E52: OM_V173043_MaFr | G52: www.makler-ergo.de
B53: 10963 Berlin | F53: PIN 2412 | G53: www.datenbereitstellung.de
E54: E843589
D55: 135886
A56: Generali | B56: Adenauer Ring 7-11 | C56: 01803 284666 | D56: 156902 | E56: Alias:FrankMal1 | F56: Sommer2018 | G56: www.maklernet.generali.de
B57: 81737 München | D57: für GDV-Daten | E57: G156902A | F57: FrankMal1 | G57: www.generali.de
A59: Gothaer | D59: 28269 | E59: V103059 | F59: Frank12M | G59: www.makler.gothaer.de
C61: Herr Lang
A62: Haftpflichtkasse Darmstadt | B62: Postfach 11 26 | C62: T 06154 601-1356 | D62: 009530-525
B63: 64373 Roßdorf | C63: F 06154/601-2356
A66: HDI | B66: Postfach 101 625 | C66: 0221 144 3001 | D66: 257544 | E66: 257544HDI | F66: AnnettWer18 | G66: www.mymaklernet.de
B67: 50456 Köln | C67: 0221 144 61975 | E67: fzf3nkf8 | F67: 42013
...
